{
 "cells": [
  {
   "cell_type": "code",
   "execution_count": 1,
   "metadata": {},
   "outputs": [],
   "source": [
    "from pymongo import MongoClient\n",
    "import glob\n",
    "import json"
   ]
  },
  {
   "cell_type": "code",
   "execution_count": 2,
   "metadata": {},
   "outputs": [],
   "source": [
    "# client = MongoClient('mongodb+srv://user:user@cluster0.ard5c.mongodb.net/test')\n",
    "client = MongoClient('mongodb://localhost:27017/')"
   ]
  },
  {
   "cell_type": "code",
   "execution_count": 3,
   "metadata": {},
   "outputs": [],
   "source": [
    "db = client.get_database('tweets')\n"
   ]
  },
  {
   "cell_type": "code",
   "execution_count": 4,
   "metadata": {},
   "outputs": [],
   "source": [
    "#TODO  57441414, 5695632 re check followers"
   ]
  },
  {
   "cell_type": "code",
   "execution_count": 5,
   "metadata": {},
   "outputs": [],
   "source": [
    "test = db['followers'].find_one({'user_id': 5695632})"
   ]
  },
  {
   "cell_type": "code",
   "execution_count": 6,
   "metadata": {},
   "outputs": [
    {
     "data": {
      "text/plain": [
       "386907"
      ]
     },
     "execution_count": 6,
     "metadata": {},
     "output_type": "execute_result"
    }
   ],
   "source": [
    "len(test['followers'])"
   ]
  },
  {
   "cell_type": "code",
   "execution_count": 7,
   "metadata": {},
   "outputs": [
    {
     "name": "stdout",
     "output_type": "stream",
     "text": [
      "nlp-dev\n"
     ]
    }
   ],
   "source": [
    "#### API Client\n",
    "\n",
    "import os\n",
    "print (os.environ['CONDA_DEFAULT_ENV'])\n",
    "\n",
    "import tweepy\n",
    "import webbrowser\n",
    "import time\n",
    "import pandas as pd\n",
    "import csv\n",
    "import json\n",
    "import requests\n",
    "\n",
    "# Dumika\n",
    "\n",
    "consumer_key = \"1ZFrXbH32jHTtAIz7sYAkttg6\"\n",
    "consumer_secret = \"kCMmzuesgQ9Ijznh7uL2gqJD1CJ1GFbhO77C8FPZ6oe7p1Fef4\"\n",
    "\n",
    "access_token = \"1315870228534845442-XD2mqQGqMScZCLlXpqP5pf5h9cxsqB\"\n",
    "token_secret = \"EvoGd8WrX748qBcX7WC0xmDgEokIOtkI1GBBGS0pqFJJV\""
   ]
  },
  {
   "cell_type": "code",
   "execution_count": 8,
   "metadata": {},
   "outputs": [],
   "source": [
    "# Authenticate to Twitter\n",
    "try:\n",
    "    auth = tweepy.OAuthHandler(consumer_key, consumer_secret)\n",
    "    auth.set_access_token(access_token, token_secret) \n",
    "except tweepy.TweepError as e:\n",
    "    print(e)\n",
    "    \n",
    "\n",
    "# Create API object\n",
    "api = tweepy.API(auth, wait_on_rate_limit=True,\n",
    "    wait_on_rate_limit_notify=True)"
   ]
  },
  {
   "cell_type": "code",
   "execution_count": 9,
   "metadata": {
    "scrolled": true,
    "tags": []
   },
   "outputs": [],
   "source": [
    "# # Group tweets by root tweet id (grater tha 200 retweets)\n",
    "\n",
    "# for rating_type in ['false']:\n",
    "#     for i in range(2, 3):\n",
    "        \n",
    "#         flag = True\n",
    "#         while flag:\n",
    "#             try:\n",
    "#                 cascade_root_user_ids = set()\n",
    "#                 # collection name\n",
    "#                 COLLECTION_NAME = 'data_{}_{}'.format(rating_type, i)\n",
    "#                 print(COLLECTION_NAME, 'trying to collect...')\n",
    "                \n",
    "#                 # populate existing user_ids\n",
    "#                 records = db['followers']\n",
    "#                 populated_documents = records.find()\n",
    "#                 populated_user_ids = []\n",
    "#                 for document in populated_documents:\n",
    "#                     populated_user_ids.append(document['user_id'])\n",
    "#                 print('Initalizing population...')\n",
    "                \n",
    "#                 records = db[COLLECTION_NAME]\n",
    "#                 cursor = records.find({'retweeted_status.retweet_count' : { '$gt' :50 } }, batch_size = 10)\n",
    "#                 for record in cursor:\n",
    "#                     user_id = record['user']['id']\n",
    "#                     if user_id not in populated_user_ids:\n",
    "#                         try:\n",
    "#                             cascade_root_user_ids.add(record['retweeted_status']['id'])\n",
    "#                             records = db['followers']               \n",
    "#                             records.insert_one({'user_id' : user_id, 'followers' : []})\n",
    "#                             try:\n",
    "#                                 print('collecting...', user_id)\n",
    "#                                 for follower in tweepy.Cursor(api.followers_ids, user_id = user_id).items(10000000):\n",
    "#                                     records.update_one({'user_id' : user_id}, {'$push' : {'followers' : follower}})\n",
    "#                             except tweepy.TweepError as e:\n",
    "#                                 if 'Failed to send request:' in e.reason:\n",
    "#                                     print('Time out error caught.')\n",
    "#                                     time.sleep(180)\n",
    "#                                     continue\n",
    "#                         except (AttributeError, KeyError) as e:\n",
    "#                             print('AttributeError, KeyError failed')\n",
    "#                             continue\n",
    "#                 cursor = records.find({'retweeted_status.retweet_count' : { '$gt' :200 } }, batch_size = 10)\n",
    "#                 user_ids = list(record['user']['id'] for record in cursor )\n",
    "#                 print(type(user_ids), len(user_ids))\n",
    "#                 print(type(populated_user_ids), len(populated_user_ids))\n",
    "#                 if set(user_ids).issubset(set(populated_user_ids)):\n",
    "#                     flag = False\n",
    "#             except Exception as e:\n",
    "#                 print(e, ' OR Connection failed')\n",
    "#                 time.sleep(180)\n",
    "#                 continue"
   ]
  },
  {
   "cell_type": "code",
   "execution_count": 10,
   "metadata": {},
   "outputs": [],
   "source": [
    "ROOT_USERS = [5695632,874488674, 16893929, 196724330, 15752235, 966317909659103232, 16012783, 5695632, 403765458, 4011928402, 16351765, 16666454, 36876990, 18927441, 25754433, 84111298, 457984599, 61558438, 519897737, 2300835530, 32913997, 882445459, 44202038, 474464413, 89005882, 335206333, 344778430, 1391686780798210052, 16640775, 287603080, 5392522, 18728203, 701725963, 318680721, 19201304, 21110041, 1138852762463154177, 847811211752243200, 14838173, 2261025822, 22705952, 18082466, 1245158946, 24736682, 900085327863218176, 428333, 1268569059731353600, 145692463, 23674801, 1381303367071305729, 17525171, 1153391118773604352, 25817278, 767609351037214720, 255801799, 126051146, 15791186, 18908628, 1359293410847383558, 780460754910732288, 14221917, 444054117, 2269308902, 14697575, 20562924, 57443437, 2828568811, 35773039, 241972592, 429112432, 931039604, 1339526904, 23447418, 4170491, 20087934, 14330880, 20402945, 3191437439, 1147804652039069696, 1329524222109097995, 14500743, 1282297722364727296, 9633802, 1052626822645596161, 25589776, 17710740, 215863060, 226024854, 1333137558893719552, 41085467, 624413, 1143770884974399488, 1295043616742805506, 295860511, 353701419, 1233104313771184129, 768552674719567876, 15108530, 17525171, 48310197, 1278251649803251713, 17852343, 19898168, 133663801, 20583993, 158865339, 472122299, 1652541, 18774524, 980924206132195328, 849800022094880768, 1371529262566608908, 63485764, 356631237, 1283802294186848257, 149516743, 96877126, 21694413, 19407053, 14946895, 16396368, 1276154115773599744, 7313362, 2987385810, 1232689061049126912, 596792665, 786324746719924224, 1260307716385443840, 1310782718603456513, 2735591, 488554346, 26329195, 23922797, 2291106157, 1303630426234408961, 15969142, 19013879, 1016487483138138112, 145802745, 17121146, 1291779641519169536, 14790524, 14594813, 1381246086363365376, 620136960, 24402433, 1370932230, 15169032, 1089607242565984258, 1294649677372153856, 163384337, 1352378437445570567, 79238164, 16973333, 1277745817386975232, 2339238427, 36008477, 809558047, 921033470712918016, 260828194, 374256165, 14301229, 988851384605913088, 2375800382, 19498559, 15438913, 809229705073147904, 17077313, 835941444, 12480582, 1190493069977632768, 21545542, 212145230, 1040650542840782848, 7744592, 989813532786077696, 3702234197, 457984599, 428649561, 747043567936352261, 14296157, 1220432811875880967, 527516258, 2778438762, 1250158141997752332, 189870199, 17602680, 18195067, 27959419, 14229123, 14173315, 224657541, 380648579, 21015687, 224374922, 940290547767496705, 2248538251, 1570225806, 1211718190255861760, 1344804182465916930, 44728980, 63944344, 9763482, 3012907162, 925728652880482305, 755114148, 3713954474, 572517552, 262168753, 14897840, 1238446299650723845, 1279908907004067842, 1126322371, 1338342474280996866, 1124066353739128832, 3315404490, 2940904657, 980540524737150976, 940801984025845761, 1374874868068548617, 1173297035367329798, 27987687, 21208813, 25508589, 19976943, 1077824277041299456, 931279170826412033, 35203319, 43901688, 1265560405314854914, 513627393, 1166384476081070081, 15792387, 16640775, 1280606167144660992, 2873884427, 3331875599, 14692117, 3156281110, 887816658877677568, 19242778, 779515880333910016, 1314655890138705924, 21748010, 758269741, 1278610637271203840, 251935030, 1305909315493130242, 14294848, 245615938, 2461887810, 50318149, 94706501, 111556423, 1332970519424102407, 1168472395, 829882414763753472, 17365337, 733005584946110465, 1195328245618491392, 1226723708871426048, 1001913176756248576, 1197684524630585345, 15969142, 1138576987948244992, 15771003, 389477245, 17908607, 1205508480, 23879043, 534079877, 3044516229, 1000132999, 2784919443, 19032473, 331700122, 1372207883903975426, 142099869, 1231516588077199360, 15872418, 3863925669, 38142380, 55615408, 138705329, 816238800569507842, 997638434394066944, 816477408391929856, 2474805697, 136514502, 16743886, 996670904523423744, 16688083, 713475201284046849, 380285402, 11928542, 9627102, 1063387106918174720, 1206794218213126144, 179903977, 1066727437533351938, 16331756, 64643056, 109975024, 1248561401196675072]"
   ]
  },
  {
   "cell_type": "code",
   "execution_count": null,
   "metadata": {
    "tags": []
   },
   "outputs": [
    {
     "name": "stdout",
     "output_type": "stream",
     "text": [
      "collecting... 966317909659103232\n",
      "collecting... 16012783\n",
      "Time out error caught. Failed to send request: HTTPSConnectionPool(host='api.twitter.com', port=443): Max retries exceeded with url: /1.1/followers/ids.json?cursor=1686604371823449848&user_id=16012783 (Caused by NewConnectionError('<urllib3.connection.VerifiedHTTPSConnection object at 0x0A604090>: Failed to establish a new connection: [Errno 11001] getaddrinfo failed'))\n",
      "collecting... 403765458\n",
      "Time out error caught. Failed to send request: HTTPSConnectionPool(host='api.twitter.com', port=443): Max retries exceeded with url: /1.1/followers/ids.json?cursor=-1&user_id=403765458 (Caused by NewConnectionError('<urllib3.connection.VerifiedHTTPSConnection object at 0x0C72F4B0>: Failed to establish a new connection: [Errno 11001] getaddrinfo failed'))\n",
      "collecting... 4011928402\n",
      "Time out error caught. Failed to send request: HTTPSConnectionPool(host='api.twitter.com', port=443): Max retries exceeded with url: /1.1/followers/ids.json?cursor=-1&user_id=4011928402 (Caused by NewConnectionError('<urllib3.connection.VerifiedHTTPSConnection object at 0x0A604FB0>: Failed to establish a new connection: [Errno 11001] getaddrinfo failed'))\n",
      "collecting... 16351765\n",
      "Time out error caught. Failed to send request: HTTPSConnectionPool(host='api.twitter.com', port=443): Max retries exceeded with url: /1.1/followers/ids.json?cursor=-1&user_id=16351765 (Caused by NewConnectionError('<urllib3.connection.VerifiedHTTPSConnection object at 0x0C72FC50>: Failed to establish a new connection: [Errno 11001] getaddrinfo failed'))\n",
      "collecting... 16666454\n",
      "Time out error caught. Failed to send request: HTTPSConnectionPool(host='api.twitter.com', port=443): Max retries exceeded with url: /1.1/followers/ids.json?cursor=-1&user_id=16666454 (Caused by NewConnectionError('<urllib3.connection.VerifiedHTTPSConnection object at 0x0C72F870>: Failed to establish a new connection: [Errno 11001] getaddrinfo failed'))\n",
      "collecting... 36876990\n",
      "Time out error caught. Failed to send request: HTTPSConnectionPool(host='api.twitter.com', port=443): Max retries exceeded with url: /1.1/followers/ids.json?cursor=-1&user_id=36876990 (Caused by NewConnectionError('<urllib3.connection.VerifiedHTTPSConnection object at 0x0B3D0C70>: Failed to establish a new connection: [Errno 11001] getaddrinfo failed'))\n",
      "collecting... 18927441\n",
      "Time out error caught. Failed to send request: HTTPSConnectionPool(host='api.twitter.com', port=443): Max retries exceeded with url: /1.1/followers/ids.json?cursor=-1&user_id=18927441 (Caused by NewConnectionError('<urllib3.connection.VerifiedHTTPSConnection object at 0x0B3D0DD0>: Failed to establish a new connection: [Errno 11001] getaddrinfo failed'))\n",
      "collecting... 25754433\n",
      "Time out error caught. Failed to send request: HTTPSConnectionPool(host='api.twitter.com', port=443): Max retries exceeded with url: /1.1/followers/ids.json?cursor=-1&user_id=25754433 (Caused by NewConnectionError('<urllib3.connection.VerifiedHTTPSConnection object at 0x0B3D0150>: Failed to establish a new connection: [Errno 11001] getaddrinfo failed'))\n",
      "collecting... 84111298\n",
      "Time out error caught. Failed to send request: HTTPSConnectionPool(host='api.twitter.com', port=443): Max retries exceeded with url: /1.1/followers/ids.json?cursor=-1&user_id=84111298 (Caused by NewConnectionError('<urllib3.connection.VerifiedHTTPSConnection object at 0x0C72F910>: Failed to establish a new connection: [Errno 11001] getaddrinfo failed'))\n",
      "collecting... 457984599\n",
      "Time out error caught. Failed to send request: HTTPSConnectionPool(host='api.twitter.com', port=443): Max retries exceeded with url: /1.1/followers/ids.json?cursor=-1&user_id=457984599 (Caused by NewConnectionError('<urllib3.connection.VerifiedHTTPSConnection object at 0x0B3D00B0>: Failed to establish a new connection: [Errno 11001] getaddrinfo failed'))\n",
      "collecting... 61558438\n",
      "Time out error caught. Failed to send request: HTTPSConnectionPool(host='api.twitter.com', port=443): Max retries exceeded with url: /1.1/followers/ids.json?cursor=-1&user_id=61558438 (Caused by NewConnectionError('<urllib3.connection.VerifiedHTTPSConnection object at 0x0B3D0310>: Failed to establish a new connection: [Errno 11001] getaddrinfo failed'))\n",
      "collecting... 519897737\n",
      "Time out error caught. Failed to send request: HTTPSConnectionPool(host='api.twitter.com', port=443): Max retries exceeded with url: /1.1/followers/ids.json?cursor=-1&user_id=519897737 (Caused by NewConnectionError('<urllib3.connection.VerifiedHTTPSConnection object at 0x0B3D0CD0>: Failed to establish a new connection: [Errno 11001] getaddrinfo failed'))\n",
      "collecting... 2300835530\n",
      "Time out error caught. Failed to send request: HTTPSConnectionPool(host='api.twitter.com', port=443): Max retries exceeded with url: /1.1/followers/ids.json?cursor=-1&user_id=2300835530 (Caused by NewConnectionError('<urllib3.connection.VerifiedHTTPSConnection object at 0x0B3D0950>: Failed to establish a new connection: [Errno 11001] getaddrinfo failed'))\n",
      "collecting... 32913997\n",
      "Time out error caught. Failed to send request: HTTPSConnectionPool(host='api.twitter.com', port=443): Max retries exceeded with url: /1.1/followers/ids.json?cursor=-1&user_id=32913997 (Caused by NewConnectionError('<urllib3.connection.VerifiedHTTPSConnection object at 0x0B3D0AB0>: Failed to establish a new connection: [Errno 11001] getaddrinfo failed'))\n",
      "collecting... 882445459\n",
      "Time out error caught. Failed to send request: HTTPSConnectionPool(host='api.twitter.com', port=443): Max retries exceeded with url: /1.1/followers/ids.json?cursor=-1&user_id=882445459 (Caused by NewConnectionError('<urllib3.connection.VerifiedHTTPSConnection object at 0x0B3D0CD0>: Failed to establish a new connection: [Errno 11001] getaddrinfo failed'))\n",
      "collecting... 44202038\n",
      "Time out error caught. Failed to send request: HTTPSConnectionPool(host='api.twitter.com', port=443): Max retries exceeded with url: /1.1/followers/ids.json?cursor=-1&user_id=44202038 (Caused by NewConnectionError('<urllib3.connection.VerifiedHTTPSConnection object at 0x0B3D0250>: Failed to establish a new connection: [Errno 11001] getaddrinfo failed'))\n",
      "collecting... 474464413\n",
      "Time out error caught. Failed to send request: HTTPSConnectionPool(host='api.twitter.com', port=443): Max retries exceeded with url: /1.1/followers/ids.json?cursor=-1&user_id=474464413 (Caused by NewConnectionError('<urllib3.connection.VerifiedHTTPSConnection object at 0x0B3D0350>: Failed to establish a new connection: [Errno 11001] getaddrinfo failed'))\n",
      "collecting... 89005882\n",
      "Time out error caught. Failed to send request: HTTPSConnectionPool(host='api.twitter.com', port=443): Max retries exceeded with url: /1.1/followers/ids.json?cursor=-1&user_id=89005882 (Caused by NewConnectionError('<urllib3.connection.VerifiedHTTPSConnection object at 0x0B3D0650>: Failed to establish a new connection: [Errno 11001] getaddrinfo failed'))\n",
      "collecting... 335206333\n",
      "Time out error caught. Failed to send request: HTTPSConnectionPool(host='api.twitter.com', port=443): Max retries exceeded with url: /1.1/followers/ids.json?cursor=-1&user_id=335206333 (Caused by NewConnectionError('<urllib3.connection.VerifiedHTTPSConnection object at 0x0B3D0170>: Failed to establish a new connection: [Errno 11001] getaddrinfo failed'))\n",
      "collecting... 344778430\n",
      "Time out error caught. Failed to send request: HTTPSConnectionPool(host='api.twitter.com', port=443): Max retries exceeded with url: /1.1/followers/ids.json?cursor=-1&user_id=344778430 (Caused by NewConnectionError('<urllib3.connection.VerifiedHTTPSConnection object at 0x08B89D10>: Failed to establish a new connection: [Errno 11001] getaddrinfo failed'))\n",
      "collecting... 1391686780798210052\n",
      "Time out error caught. Failed to send request: HTTPSConnectionPool(host='api.twitter.com', port=443): Max retries exceeded with url: /1.1/followers/ids.json?cursor=-1&user_id=1391686780798210052 (Caused by NewConnectionError('<urllib3.connection.VerifiedHTTPSConnection object at 0x0C72F290>: Failed to establish a new connection: [Errno 11001] getaddrinfo failed'))\n",
      "collecting... 16640775\n",
      "Time out error caught. Failed to send request: HTTPSConnectionPool(host='api.twitter.com', port=443): Max retries exceeded with url: /1.1/followers/ids.json?cursor=-1&user_id=16640775 (Caused by NewConnectionError('<urllib3.connection.VerifiedHTTPSConnection object at 0x086CD3B0>: Failed to establish a new connection: [Errno 11001] getaddrinfo failed'))\n",
      "collecting... 287603080\n",
      "Time out error caught. Failed to send request: HTTPSConnectionPool(host='api.twitter.com', port=443): Max retries exceeded with url: /1.1/followers/ids.json?cursor=-1&user_id=287603080 (Caused by NewConnectionError('<urllib3.connection.VerifiedHTTPSConnection object at 0x0C72F8F0>: Failed to establish a new connection: [Errno 11001] getaddrinfo failed'))\n",
      "collecting... 5392522\n",
      "Time out error caught. Failed to send request: HTTPSConnectionPool(host='api.twitter.com', port=443): Max retries exceeded with url: /1.1/followers/ids.json?cursor=-1&user_id=5392522 (Caused by NewConnectionError('<urllib3.connection.VerifiedHTTPSConnection object at 0x0C72F7F0>: Failed to establish a new connection: [Errno 11001] getaddrinfo failed'))\n",
      "collecting... 18728203\n",
      "Time out error caught. Failed to send request: HTTPSConnectionPool(host='api.twitter.com', port=443): Max retries exceeded with url: /1.1/followers/ids.json?cursor=-1&user_id=18728203 (Caused by NewConnectionError('<urllib3.connection.VerifiedHTTPSConnection object at 0x0A604870>: Failed to establish a new connection: [Errno 11001] getaddrinfo failed'))\n",
      "collecting... 318680721\n",
      "Time out error caught. Failed to send request: HTTPSConnectionPool(host='api.twitter.com', port=443): Max retries exceeded with url: /1.1/followers/ids.json?cursor=-1&user_id=318680721 (Caused by NewConnectionError('<urllib3.connection.VerifiedHTTPSConnection object at 0x0C72F890>: Failed to establish a new connection: [Errno 11001] getaddrinfo failed'))\n",
      "collecting... 19201304\n",
      "Time out error caught. Failed to send request: HTTPSConnectionPool(host='api.twitter.com', port=443): Max retries exceeded with url: /1.1/followers/ids.json?cursor=-1&user_id=19201304 (Caused by NewConnectionError('<urllib3.connection.VerifiedHTTPSConnection object at 0x0C72F2D0>: Failed to establish a new connection: [Errno 11001] getaddrinfo failed'))\n",
      "collecting... 21110041\n",
      "Time out error caught. Failed to send request: HTTPSConnectionPool(host='api.twitter.com', port=443): Max retries exceeded with url: /1.1/followers/ids.json?cursor=-1&user_id=21110041 (Caused by NewConnectionError('<urllib3.connection.VerifiedHTTPSConnection object at 0x08B89D10>: Failed to establish a new connection: [Errno 11001] getaddrinfo failed'))\n",
      "collecting... 1138852762463154177\n",
      "Time out error caught. Failed to send request: HTTPSConnectionPool(host='api.twitter.com', port=443): Max retries exceeded with url: /1.1/followers/ids.json?cursor=-1&user_id=1138852762463154177 (Caused by NewConnectionError('<urllib3.connection.VerifiedHTTPSConnection object at 0x0B3D06F0>: Failed to establish a new connection: [Errno 11001] getaddrinfo failed'))\n",
      "collecting... 847811211752243200\n",
      "Time out error caught. Failed to send request: HTTPSConnectionPool(host='api.twitter.com', port=443): Max retries exceeded with url: /1.1/followers/ids.json?cursor=-1&user_id=847811211752243200 (Caused by NewConnectionError('<urllib3.connection.VerifiedHTTPSConnection object at 0x0B3D0890>: Failed to establish a new connection: [Errno 11001] getaddrinfo failed'))\n",
      "collecting... 14838173\n",
      "Time out error caught. Failed to send request: HTTPSConnectionPool(host='api.twitter.com', port=443): Max retries exceeded with url: /1.1/followers/ids.json?cursor=-1&user_id=14838173 (Caused by NewConnectionError('<urllib3.connection.VerifiedHTTPSConnection object at 0x0B3D02B0>: Failed to establish a new connection: [Errno 11001] getaddrinfo failed'))\n",
      "collecting... 2261025822\n",
      "Time out error caught. Failed to send request: HTTPSConnectionPool(host='api.twitter.com', port=443): Max retries exceeded with url: /1.1/followers/ids.json?cursor=-1&user_id=2261025822 (Caused by NewConnectionError('<urllib3.connection.VerifiedHTTPSConnection object at 0x08BCEEB0>: Failed to establish a new connection: [Errno 11001] getaddrinfo failed'))\n",
      "collecting... 22705952\n",
      "Time out error caught. Failed to send request: HTTPSConnectionPool(host='api.twitter.com', port=443): Max retries exceeded with url: /1.1/followers/ids.json?cursor=-1&user_id=22705952 (Caused by NewConnectionError('<urllib3.connection.VerifiedHTTPSConnection object at 0x08BCEEB0>: Failed to establish a new connection: [Errno 11001] getaddrinfo failed'))\n",
      "collecting... 18082466\n",
      "Time out error caught. Failed to send request: HTTPSConnectionPool(host='api.twitter.com', port=443): Max retries exceeded with url: /1.1/followers/ids.json?cursor=-1&user_id=18082466 (Caused by NewConnectionError('<urllib3.connection.VerifiedHTTPSConnection object at 0x08A69990>: Failed to establish a new connection: [Errno 11001] getaddrinfo failed'))\n",
      "collecting... 1245158946\n",
      "Time out error caught. Failed to send request: HTTPSConnectionPool(host='api.twitter.com', port=443): Max retries exceeded with url: /1.1/followers/ids.json?cursor=-1&user_id=1245158946 (Caused by NewConnectionError('<urllib3.connection.VerifiedHTTPSConnection object at 0x08A69990>: Failed to establish a new connection: [Errno 11001] getaddrinfo failed'))\n",
      "collecting... 24736682\n",
      "Time out error caught. Failed to send request: HTTPSConnectionPool(host='api.twitter.com', port=443): Max retries exceeded with url: /1.1/followers/ids.json?cursor=-1&user_id=24736682 (Caused by NewConnectionError('<urllib3.connection.VerifiedHTTPSConnection object at 0x0A604750>: Failed to establish a new connection: [Errno 11001] getaddrinfo failed'))\n",
      "collecting... 900085327863218176\n",
      "Time out error caught. Failed to send request: HTTPSConnectionPool(host='api.twitter.com', port=443): Max retries exceeded with url: /1.1/followers/ids.json?cursor=-1&user_id=900085327863218176 (Caused by NewConnectionError('<urllib3.connection.VerifiedHTTPSConnection object at 0x05AF89B0>: Failed to establish a new connection: [Errno 11001] getaddrinfo failed'))\n",
      "collecting... 428333\n",
      "Time out error caught. Failed to send request: HTTPSConnectionPool(host='api.twitter.com', port=443): Max retries exceeded with url: /1.1/followers/ids.json?cursor=-1&user_id=428333 (Caused by NewConnectionError('<urllib3.connection.VerifiedHTTPSConnection object at 0x0B3D07D0>: Failed to establish a new connection: [Errno 11001] getaddrinfo failed'))\n",
      "collecting... 1268569059731353600\n",
      "Time out error caught. Failed to send request: HTTPSConnectionPool(host='api.twitter.com', port=443): Max retries exceeded with url: /1.1/followers/ids.json?cursor=-1&user_id=1268569059731353600 (Caused by NewConnectionError('<urllib3.connection.VerifiedHTTPSConnection object at 0x0B3D0AD0>: Failed to establish a new connection: [Errno 11001] getaddrinfo failed'))\n",
      "collecting... 145692463\n",
      "Time out error caught. Failed to send request: HTTPSConnectionPool(host='api.twitter.com', port=443): Max retries exceeded with url: /1.1/followers/ids.json?cursor=-1&user_id=145692463 (Caused by NewConnectionError('<urllib3.connection.VerifiedHTTPSConnection object at 0x0B3D0510>: Failed to establish a new connection: [Errno 11001] getaddrinfo failed'))\n",
      "collecting... 23674801\n",
      "Time out error caught. Failed to send request: HTTPSConnectionPool(host='api.twitter.com', port=443): Max retries exceeded with url: /1.1/followers/ids.json?cursor=-1&user_id=23674801 (Caused by NewConnectionError('<urllib3.connection.VerifiedHTTPSConnection object at 0x08BCEE30>: Failed to establish a new connection: [Errno 11001] getaddrinfo failed'))\n",
      "collecting... 1381303367071305729\n",
      "Time out error caught. Failed to send request: HTTPSConnectionPool(host='api.twitter.com', port=443): Max retries exceeded with url: /1.1/followers/ids.json?cursor=-1&user_id=1381303367071305729 (Caused by NewConnectionError('<urllib3.connection.VerifiedHTTPSConnection object at 0x08BCEE30>: Failed to establish a new connection: [Errno 11001] getaddrinfo failed'))\n",
      "collecting... 17525171\n",
      "Time out error caught. Failed to send request: HTTPSConnectionPool(host='api.twitter.com', port=443): Max retries exceeded with url: /1.1/followers/ids.json?cursor=-1&user_id=17525171 (Caused by NewConnectionError('<urllib3.connection.VerifiedHTTPSConnection object at 0x0C72F950>: Failed to establish a new connection: [Errno 11001] getaddrinfo failed'))\n",
      "collecting... 1153391118773604352\n",
      "Time out error caught. Failed to send request: HTTPSConnectionPool(host='api.twitter.com', port=443): Max retries exceeded with url: /1.1/followers/ids.json?cursor=-1&user_id=1153391118773604352 (Caused by NewConnectionError('<urllib3.connection.VerifiedHTTPSConnection object at 0x08A69990>: Failed to establish a new connection: [Errno 11001] getaddrinfo failed'))\n",
      "collecting... 25817278\n",
      "Time out error caught. Failed to send request: HTTPSConnectionPool(host='api.twitter.com', port=443): Max retries exceeded with url: /1.1/followers/ids.json?cursor=-1&user_id=25817278 (Caused by NewConnectionError('<urllib3.connection.VerifiedHTTPSConnection object at 0x05AF89B0>: Failed to establish a new connection: [Errno 11001] getaddrinfo failed'))\n",
      "collecting... 767609351037214720\n",
      "Time out error caught. Failed to send request: HTTPSConnectionPool(host='api.twitter.com', port=443): Max retries exceeded with url: /1.1/followers/ids.json?cursor=-1&user_id=767609351037214720 (Caused by NewConnectionError('<urllib3.connection.VerifiedHTTPSConnection object at 0x05BFF350>: Failed to establish a new connection: [Errno 11001] getaddrinfo failed'))\n",
      "collecting... 255801799\n",
      "Time out error caught. Failed to send request: HTTPSConnectionPool(host='api.twitter.com', port=443): Max retries exceeded with url: /1.1/followers/ids.json?cursor=-1&user_id=255801799 (Caused by NewConnectionError('<urllib3.connection.VerifiedHTTPSConnection object at 0x0A604390>: Failed to establish a new connection: [Errno 11001] getaddrinfo failed'))\n",
      "collecting... 126051146\n",
      "Time out error caught. Failed to send request: HTTPSConnectionPool(host='api.twitter.com', port=443): Max retries exceeded with url: /1.1/followers/ids.json?cursor=-1&user_id=126051146 (Caused by NewConnectionError('<urllib3.connection.VerifiedHTTPSConnection object at 0x08B748B0>: Failed to establish a new connection: [Errno 11001] getaddrinfo failed'))\n",
      "collecting... 15791186\n",
      "Time out error caught. Failed to send request: HTTPSConnectionPool(host='api.twitter.com', port=443): Max retries exceeded with url: /1.1/followers/ids.json?cursor=-1&user_id=15791186 (Caused by NewConnectionError('<urllib3.connection.VerifiedHTTPSConnection object at 0x0B3D0E90>: Failed to establish a new connection: [Errno 11001] getaddrinfo failed'))\n",
      "collecting... 18908628\n",
      "Time out error caught. Failed to send request: HTTPSConnectionPool(host='api.twitter.com', port=443): Max retries exceeded with url: /1.1/followers/ids.json?cursor=-1&user_id=18908628 (Caused by NewConnectionError('<urllib3.connection.VerifiedHTTPSConnection object at 0x0B3D0910>: Failed to establish a new connection: [Errno 11001] getaddrinfo failed'))\n",
      "collecting... 1359293410847383558\n",
      "Time out error caught. Failed to send request: HTTPSConnectionPool(host='api.twitter.com', port=443): Max retries exceeded with url: /1.1/followers/ids.json?cursor=-1&user_id=1359293410847383558 (Caused by NewConnectionError('<urllib3.connection.VerifiedHTTPSConnection object at 0x0C72F470>: Failed to establish a new connection: [Errno 11001] getaddrinfo failed'))\n",
      "collecting... 780460754910732288\n",
      "Time out error caught. Failed to send request: HTTPSConnectionPool(host='api.twitter.com', port=443): Max retries exceeded with url: /1.1/followers/ids.json?cursor=-1&user_id=780460754910732288 (Caused by NewConnectionError('<urllib3.connection.VerifiedHTTPSConnection object at 0x0B3D0810>: Failed to establish a new connection: [Errno 11001] getaddrinfo failed'))\n",
      "collecting... 14221917\n",
      "Time out error caught. Failed to send request: HTTPSConnectionPool(host='api.twitter.com', port=443): Max retries exceeded with url: /1.1/followers/ids.json?cursor=-1&user_id=14221917 (Caused by NewConnectionError('<urllib3.connection.VerifiedHTTPSConnection object at 0x0B3D0290>: Failed to establish a new connection: [Errno 11001] getaddrinfo failed'))\n",
      "collecting... 444054117\n",
      "Time out error caught. Failed to send request: HTTPSConnectionPool(host='api.twitter.com', port=443): Max retries exceeded with url: /1.1/followers/ids.json?cursor=-1&user_id=444054117 (Caused by NewConnectionError('<urllib3.connection.VerifiedHTTPSConnection object at 0x06847770>: Failed to establish a new connection: [Errno 11001] getaddrinfo failed'))\n",
      "collecting... 2269308902\n",
      "Time out error caught. Failed to send request: HTTPSConnectionPool(host='api.twitter.com', port=443): Max retries exceeded with url: /1.1/followers/ids.json?cursor=-1&user_id=2269308902 (Caused by NewConnectionError('<urllib3.connection.VerifiedHTTPSConnection object at 0x0B3D0050>: Failed to establish a new connection: [Errno 11001] getaddrinfo failed'))\n",
      "collecting... 14697575\n",
      "Time out error caught. Failed to send request: HTTPSConnectionPool(host='api.twitter.com', port=443): Max retries exceeded with url: /1.1/followers/ids.json?cursor=-1&user_id=14697575 (Caused by NewConnectionError('<urllib3.connection.VerifiedHTTPSConnection object at 0x0A604230>: Failed to establish a new connection: [Errno 11001] getaddrinfo failed'))\n",
      "collecting... 20562924\n",
      "Time out error caught. Failed to send request: HTTPSConnectionPool(host='api.twitter.com', port=443): Max retries exceeded with url: /1.1/followers/ids.json?cursor=-1&user_id=20562924 (Caused by NewConnectionError('<urllib3.connection.VerifiedHTTPSConnection object at 0x0A604910>: Failed to establish a new connection: [Errno 11001] getaddrinfo failed'))\n",
      "collecting... 57443437\n",
      "Time out error caught. Failed to send request: HTTPSConnectionPool(host='api.twitter.com', port=443): Max retries exceeded with url: /1.1/followers/ids.json?cursor=-1&user_id=57443437 (Caused by NewConnectionError('<urllib3.connection.VerifiedHTTPSConnection object at 0x0A6042B0>: Failed to establish a new connection: [Errno 11001] getaddrinfo failed'))\n",
      "collecting... 2828568811\n",
      "Time out error caught. Failed to send request: HTTPSConnectionPool(host='api.twitter.com', port=443): Max retries exceeded with url: /1.1/followers/ids.json?cursor=-1&user_id=2828568811 (Caused by NewConnectionError('<urllib3.connection.VerifiedHTTPSConnection object at 0x0B3D0DD0>: Failed to establish a new connection: [Errno 11001] getaddrinfo failed'))\n",
      "collecting... 35773039\n",
      "Time out error caught. Failed to send request: HTTPSConnectionPool(host='api.twitter.com', port=443): Max retries exceeded with url: /1.1/followers/ids.json?cursor=-1&user_id=35773039 (Caused by NewConnectionError('<urllib3.connection.VerifiedHTTPSConnection object at 0x0B3D06D0>: Failed to establish a new connection: [Errno 11001] getaddrinfo failed'))\n",
      "collecting... 241972592\n",
      "Time out error caught. Failed to send request: HTTPSConnectionPool(host='api.twitter.com', port=443): Max retries exceeded with url: /1.1/followers/ids.json?cursor=-1&user_id=241972592 (Caused by NewConnectionError('<urllib3.connection.VerifiedHTTPSConnection object at 0x08AA1630>: Failed to establish a new connection: [Errno 11001] getaddrinfo failed'))\n",
      "collecting... 429112432\n",
      "Time out error caught. Failed to send request: HTTPSConnectionPool(host='api.twitter.com', port=443): Max retries exceeded with url: /1.1/followers/ids.json?cursor=-1&user_id=429112432 (Caused by NewConnectionError('<urllib3.connection.VerifiedHTTPSConnection object at 0x0B3D0490>: Failed to establish a new connection: [Errno 11001] getaddrinfo failed'))\n",
      "collecting... 931039604\n",
      "Time out error caught. Failed to send request: HTTPSConnectionPool(host='api.twitter.com', port=443): Max retries exceeded with url: /1.1/followers/ids.json?cursor=-1&user_id=931039604 (Caused by NewConnectionError('<urllib3.connection.VerifiedHTTPSConnection object at 0x0B3D0AD0>: Failed to establish a new connection: [Errno 11001] getaddrinfo failed'))\n",
      "collecting... 1339526904\n",
      "Time out error caught. Failed to send request: HTTPSConnectionPool(host='api.twitter.com', port=443): Max retries exceeded with url: /1.1/followers/ids.json?cursor=-1&user_id=1339526904 (Caused by NewConnectionError('<urllib3.connection.VerifiedHTTPSConnection object at 0x0C72F7D0>: Failed to establish a new connection: [Errno 11001] getaddrinfo failed'))\n",
      "collecting... 23447418\n",
      "Time out error caught. Failed to send request: HTTPSConnectionPool(host='api.twitter.com', port=443): Max retries exceeded with url: /1.1/followers/ids.json?cursor=-1&user_id=23447418 (Caused by NewConnectionError('<urllib3.connection.VerifiedHTTPSConnection object at 0x0C72F710>: Failed to establish a new connection: [Errno 11001] getaddrinfo failed'))\n",
      "collecting... 4170491\n",
      "Time out error caught. Failed to send request: HTTPSConnectionPool(host='api.twitter.com', port=443): Max retries exceeded with url: /1.1/followers/ids.json?cursor=-1&user_id=4170491 (Caused by NewConnectionError('<urllib3.connection.VerifiedHTTPSConnection object at 0x06847770>: Failed to establish a new connection: [Errno 11001] getaddrinfo failed'))\n",
      "collecting... 20087934\n",
      "Time out error caught. Failed to send request: HTTPSConnectionPool(host='api.twitter.com', port=443): Max retries exceeded with url: /1.1/followers/ids.json?cursor=-1&user_id=20087934 (Caused by NewConnectionError('<urllib3.connection.VerifiedHTTPSConnection object at 0x05BFF350>: Failed to establish a new connection: [Errno 11001] getaddrinfo failed'))\n",
      "collecting... 14330880\n",
      "Time out error caught. Failed to send request: HTTPSConnectionPool(host='api.twitter.com', port=443): Max retries exceeded with url: /1.1/followers/ids.json?cursor=-1&user_id=14330880 (Caused by NewConnectionError('<urllib3.connection.VerifiedHTTPSConnection object at 0x05B35D30>: Failed to establish a new connection: [Errno 11001] getaddrinfo failed'))\n",
      "collecting... 20402945\n",
      "Time out error caught. Failed to send request: HTTPSConnectionPool(host='api.twitter.com', port=443): Max retries exceeded with url: /1.1/followers/ids.json?cursor=-1&user_id=20402945 (Caused by NewConnectionError('<urllib3.connection.VerifiedHTTPSConnection object at 0x0A604CB0>: Failed to establish a new connection: [Errno 11001] getaddrinfo failed'))\n",
      "collecting... 3191437439\n",
      "Time out error caught. Failed to send request: HTTPSConnectionPool(host='api.twitter.com', port=443): Max retries exceeded with url: /1.1/followers/ids.json?cursor=-1&user_id=3191437439 (Caused by NewConnectionError('<urllib3.connection.VerifiedHTTPSConnection object at 0x08A78C10>: Failed to establish a new connection: [Errno 11001] getaddrinfo failed'))\n",
      "collecting... 1147804652039069696\n",
      "Time out error caught. Failed to send request: HTTPSConnectionPool(host='api.twitter.com', port=443): Max retries exceeded with url: /1.1/followers/ids.json?cursor=-1&user_id=1147804652039069696 (Caused by NewConnectionError('<urllib3.connection.VerifiedHTTPSConnection object at 0x0C72FED0>: Failed to establish a new connection: [Errno 11001] getaddrinfo failed'))\n",
      "collecting... 1329524222109097995\n",
      "Time out error caught. Failed to send request: HTTPSConnectionPool(host='api.twitter.com', port=443): Max retries exceeded with url: /1.1/followers/ids.json?cursor=-1&user_id=1329524222109097995 (Caused by NewConnectionError('<urllib3.connection.VerifiedHTTPSConnection object at 0x05BFFDD0>: Failed to establish a new connection: [Errno 11001] getaddrinfo failed'))\n",
      "collecting... 14500743\n",
      "Time out error caught. Failed to send request: HTTPSConnectionPool(host='api.twitter.com', port=443): Max retries exceeded with url: /1.1/followers/ids.json?cursor=-1&user_id=14500743 (Caused by NewConnectionError('<urllib3.connection.VerifiedHTTPSConnection object at 0x0B3D0BD0>: Failed to establish a new connection: [Errno 11001] getaddrinfo failed'))\n",
      "collecting... 9633802\n",
      "Time out error caught. Failed to send request: HTTPSConnectionPool(host='api.twitter.com', port=443): Max retries exceeded with url: /1.1/followers/ids.json?cursor=-1&user_id=9633802 (Caused by NewConnectionError('<urllib3.connection.VerifiedHTTPSConnection object at 0x0B3D0B10>: Failed to establish a new connection: [Errno 11001] getaddrinfo failed'))\n",
      "collecting... 1052626822645596161\n",
      "Time out error caught. Failed to send request: HTTPSConnectionPool(host='api.twitter.com', port=443): Max retries exceeded with url: /1.1/followers/ids.json?cursor=-1&user_id=1052626822645596161 (Caused by NewConnectionError('<urllib3.connection.VerifiedHTTPSConnection object at 0x05BFFDD0>: Failed to establish a new connection: [Errno 11001] getaddrinfo failed'))\n",
      "collecting... 25589776\n",
      "Time out error caught. Failed to send request: HTTPSConnectionPool(host='api.twitter.com', port=443): Max retries exceeded with url: /1.1/followers/ids.json?cursor=-1&user_id=25589776 (Caused by NewConnectionError('<urllib3.connection.VerifiedHTTPSConnection object at 0x08A78C10>: Failed to establish a new connection: [Errno 11001] getaddrinfo failed'))\n",
      "collecting... 17710740\n",
      "Time out error caught. Failed to send request: HTTPSConnectionPool(host='api.twitter.com', port=443): Max retries exceeded with url: /1.1/followers/ids.json?cursor=-1&user_id=17710740 (Caused by NewConnectionError('<urllib3.connection.VerifiedHTTPSConnection object at 0x0A6045B0>: Failed to establish a new connection: [Errno 11001] getaddrinfo failed'))\n",
      "collecting... 215863060\n",
      "Time out error caught. Failed to send request: HTTPSConnectionPool(host='api.twitter.com', port=443): Max retries exceeded with url: /1.1/followers/ids.json?cursor=-1&user_id=215863060 (Caused by NewConnectionError('<urllib3.connection.VerifiedHTTPSConnection object at 0x0A604110>: Failed to establish a new connection: [Errno 11001] getaddrinfo failed'))\n",
      "collecting... 226024854\n",
      "Time out error caught. Failed to send request: HTTPSConnectionPool(host='api.twitter.com', port=443): Max retries exceeded with url: /1.1/followers/ids.json?cursor=-1&user_id=226024854 (Caused by NewConnectionError('<urllib3.connection.VerifiedHTTPSConnection object at 0x0A604230>: Failed to establish a new connection: [Errno 11001] getaddrinfo failed'))\n",
      "collecting... 1333137558893719552\n",
      "Time out error caught. Failed to send request: HTTPSConnectionPool(host='api.twitter.com', port=443): Max retries exceeded with url: /1.1/followers/ids.json?cursor=-1&user_id=1333137558893719552 (Caused by NewConnectionError('<urllib3.connection.VerifiedHTTPSConnection object at 0x0A604D30>: Failed to establish a new connection: [Errno 11001] getaddrinfo failed'))\n",
      "collecting... 41085467\n",
      "Time out error caught. Failed to send request: HTTPSConnectionPool(host='api.twitter.com', port=443): Max retries exceeded with url: /1.1/followers/ids.json?cursor=-1&user_id=41085467 (Caused by NewConnectionError('<urllib3.connection.VerifiedHTTPSConnection object at 0x08AA1630>: Failed to establish a new connection: [Errno 11001] getaddrinfo failed'))\n",
      "collecting... 624413\n",
      "Time out error caught. Failed to send request: HTTPSConnectionPool(host='api.twitter.com', port=443): Max retries exceeded with url: /1.1/followers/ids.json?cursor=-1&user_id=624413 (Caused by NewConnectionError('<urllib3.connection.VerifiedHTTPSConnection object at 0x05BFFDD0>: Failed to establish a new connection: [Errno 11001] getaddrinfo failed'))\n",
      "collecting... 1295043616742805506\n",
      "Time out error caught. Failed to send request: HTTPSConnectionPool(host='api.twitter.com', port=443): Max retries exceeded with url: /1.1/followers/ids.json?cursor=-1&user_id=1295043616742805506 (Caused by NewConnectionError('<urllib3.connection.VerifiedHTTPSConnection object at 0x0B3D05F0>: Failed to establish a new connection: [Errno 11001] getaddrinfo failed'))\n",
      "collecting... 295860511\n",
      "Time out error caught. Failed to send request: HTTPSConnectionPool(host='api.twitter.com', port=443): Max retries exceeded with url: /1.1/followers/ids.json?cursor=-1&user_id=295860511 (Caused by NewConnectionError('<urllib3.connection.VerifiedHTTPSConnection object at 0x08BCEC30>: Failed to establish a new connection: [Errno 11001] getaddrinfo failed'))\n",
      "collecting... 353701419\n",
      "Time out error caught. Failed to send request: HTTPSConnectionPool(host='api.twitter.com', port=443): Max retries exceeded with url: /1.1/followers/ids.json?cursor=-1&user_id=353701419 (Caused by NewConnectionError('<urllib3.connection.VerifiedHTTPSConnection object at 0x0B3D0E30>: Failed to establish a new connection: [Errno 11001] getaddrinfo failed'))\n",
      "collecting... 1233104313771184129\n",
      "Time out error caught. Failed to send request: HTTPSConnectionPool(host='api.twitter.com', port=443): Max retries exceeded with url: /1.1/followers/ids.json?cursor=-1&user_id=1233104313771184129 (Caused by NewConnectionError('<urllib3.connection.VerifiedHTTPSConnection object at 0x08B748B0>: Failed to establish a new connection: [Errno 11001] getaddrinfo failed'))\n",
      "collecting... 768552674719567876\n",
      "Time out error caught. Failed to send request: HTTPSConnectionPool(host='api.twitter.com', port=443): Max retries exceeded with url: /1.1/followers/ids.json?cursor=-1&user_id=768552674719567876 (Caused by NewConnectionError('<urllib3.connection.VerifiedHTTPSConnection object at 0x0C72F390>: Failed to establish a new connection: [Errno 11001] getaddrinfo failed'))\n",
      "collecting... 15108530\n",
      "Time out error caught. Failed to send request: HTTPSConnectionPool(host='api.twitter.com', port=443): Max retries exceeded with url: /1.1/followers/ids.json?cursor=-1&user_id=15108530 (Caused by NewConnectionError('<urllib3.connection.VerifiedHTTPSConnection object at 0x08B748B0>: Failed to establish a new connection: [Errno 11001] getaddrinfo failed'))\n",
      "collecting... 17525171\n",
      "Time out error caught. Failed to send request: HTTPSConnectionPool(host='api.twitter.com', port=443): Max retries exceeded with url: /1.1/followers/ids.json?cursor=-1&user_id=17525171 (Caused by NewConnectionError('<urllib3.connection.VerifiedHTTPSConnection object at 0x0A6045D0>: Failed to establish a new connection: [Errno 11001] getaddrinfo failed'))\n",
      "collecting... 1278251649803251713\n",
      "Time out error caught. Failed to send request: HTTPSConnectionPool(host='api.twitter.com', port=443): Max retries exceeded with url: /1.1/followers/ids.json?cursor=-1&user_id=1278251649803251713 (Caused by NewConnectionError('<urllib3.connection.VerifiedHTTPSConnection object at 0x0A6040B0>: Failed to establish a new connection: [Errno 11001] getaddrinfo failed'))\n",
      "collecting... 17852343\n",
      "Time out error caught. Failed to send request: HTTPSConnectionPool(host='api.twitter.com', port=443): Max retries exceeded with url: /1.1/followers/ids.json?cursor=-1&user_id=17852343 (Caused by NewConnectionError('<urllib3.connection.VerifiedHTTPSConnection object at 0x0A6046B0>: Failed to establish a new connection: [Errno 11001] getaddrinfo failed'))\n",
      "collecting... 19898168\n",
      "Time out error caught. Failed to send request: HTTPSConnectionPool(host='api.twitter.com', port=443): Max retries exceeded with url: /1.1/followers/ids.json?cursor=-1&user_id=19898168 (Caused by NewConnectionError('<urllib3.connection.VerifiedHTTPSConnection object at 0x08BCEE30>: Failed to establish a new connection: [Errno 11001] getaddrinfo failed'))\n",
      "collecting... 133663801\n",
      "Time out error caught. Failed to send request: HTTPSConnectionPool(host='api.twitter.com', port=443): Max retries exceeded with url: /1.1/followers/ids.json?cursor=-1&user_id=133663801 (Caused by NewConnectionError('<urllib3.connection.VerifiedHTTPSConnection object at 0x0B3D0A30>: Failed to establish a new connection: [Errno 11001] getaddrinfo failed'))\n",
      "collecting... 20583993\n",
      "Time out error caught. Failed to send request: HTTPSConnectionPool(host='api.twitter.com', port=443): Max retries exceeded with url: /1.1/followers/ids.json?cursor=-1&user_id=20583993 (Caused by NewConnectionError('<urllib3.connection.VerifiedHTTPSConnection object at 0x0B3D0A90>: Failed to establish a new connection: [Errno 11001] getaddrinfo failed'))\n",
      "collecting... 158865339\n",
      "Time out error caught. Failed to send request: HTTPSConnectionPool(host='api.twitter.com', port=443): Max retries exceeded with url: /1.1/followers/ids.json?cursor=-1&user_id=158865339 (Caused by NewConnectionError('<urllib3.connection.VerifiedHTTPSConnection object at 0x0B3D09F0>: Failed to establish a new connection: [Errno 11001] getaddrinfo failed'))\n",
      "collecting... 472122299\n",
      "Time out error caught. Failed to send request: HTTPSConnectionPool(host='api.twitter.com', port=443): Max retries exceeded with url: /1.1/followers/ids.json?cursor=-1&user_id=472122299 (Caused by NewConnectionError('<urllib3.connection.VerifiedHTTPSConnection object at 0x0B3D02F0>: Failed to establish a new connection: [Errno 11001] getaddrinfo failed'))\n",
      "collecting... 1652541\n",
      "Time out error caught. Failed to send request: HTTPSConnectionPool(host='api.twitter.com', port=443): Max retries exceeded with url: /1.1/followers/ids.json?cursor=-1&user_id=1652541 (Caused by NewConnectionError('<urllib3.connection.VerifiedHTTPSConnection object at 0x0B3D0AB0>: Failed to establish a new connection: [Errno 11001] getaddrinfo failed'))\n",
      "collecting... 18774524\n",
      "Time out error caught. Failed to send request: HTTPSConnectionPool(host='api.twitter.com', port=443): Max retries exceeded with url: /1.1/followers/ids.json?cursor=-1&user_id=18774524 (Caused by NewConnectionError('<urllib3.connection.VerifiedHTTPSConnection object at 0x0A6045D0>: Failed to establish a new connection: [Errno 11001] getaddrinfo failed'))\n",
      "collecting... 980924206132195328\n",
      "Time out error caught. Failed to send request: HTTPSConnectionPool(host='api.twitter.com', port=443): Max retries exceeded with url: /1.1/followers/ids.json?cursor=-1&user_id=980924206132195328 (Caused by NewConnectionError('<urllib3.connection.VerifiedHTTPSConnection object at 0x08BCEF70>: Failed to establish a new connection: [Errno 11001] getaddrinfo failed'))\n",
      "collecting... 849800022094880768\n",
      "Time out error caught. Failed to send request: HTTPSConnectionPool(host='api.twitter.com', port=443): Max retries exceeded with url: /1.1/followers/ids.json?cursor=-1&user_id=849800022094880768 (Caused by NewConnectionError('<urllib3.connection.VerifiedHTTPSConnection object at 0x0A604F70>: Failed to establish a new connection: [Errno 11001] getaddrinfo failed'))\n",
      "collecting... 1371529262566608908\n",
      "Time out error caught. Failed to send request: HTTPSConnectionPool(host='api.twitter.com', port=443): Max retries exceeded with url: /1.1/followers/ids.json?cursor=-1&user_id=1371529262566608908 (Caused by NewConnectionError('<urllib3.connection.VerifiedHTTPSConnection object at 0x090510F0>: Failed to establish a new connection: [Errno 11001] getaddrinfo failed'))\n",
      "collecting... 63485764\n",
      "Time out error caught. Failed to send request: HTTPSConnectionPool(host='api.twitter.com', port=443): Max retries exceeded with url: /1.1/followers/ids.json?cursor=-1&user_id=63485764 (Caused by NewConnectionError('<urllib3.connection.VerifiedHTTPSConnection object at 0x0A604330>: Failed to establish a new connection: [Errno 11001] getaddrinfo failed'))\n",
      "collecting... 356631237\n",
      "Time out error caught. Failed to send request: HTTPSConnectionPool(host='api.twitter.com', port=443): Max retries exceeded with url: /1.1/followers/ids.json?cursor=-1&user_id=356631237 (Caused by NewConnectionError('<urllib3.connection.VerifiedHTTPSConnection object at 0x0A6043D0>: Failed to establish a new connection: [Errno 11001] getaddrinfo failed'))\n",
      "collecting... 1283802294186848257\n",
      "Time out error caught. Failed to send request: HTTPSConnectionPool(host='api.twitter.com', port=443): Max retries exceeded with url: /1.1/followers/ids.json?cursor=-1&user_id=1283802294186848257 (Caused by NewConnectionError('<urllib3.connection.VerifiedHTTPSConnection object at 0x0C72FED0>: Failed to establish a new connection: [Errno 11001] getaddrinfo failed'))\n",
      "collecting... 149516743\n",
      "Time out error caught. Failed to send request: HTTPSConnectionPool(host='api.twitter.com', port=443): Max retries exceeded with url: /1.1/followers/ids.json?cursor=-1&user_id=149516743 (Caused by NewConnectionError('<urllib3.connection.VerifiedHTTPSConnection object at 0x0C72F4F0>: Failed to establish a new connection: [Errno 11001] getaddrinfo failed'))\n",
      "collecting... 96877126\n",
      "Time out error caught. Failed to send request: HTTPSConnectionPool(host='api.twitter.com', port=443): Max retries exceeded with url: /1.1/followers/ids.json?cursor=-1&user_id=96877126 (Caused by NewConnectionError('<urllib3.connection.VerifiedHTTPSConnection object at 0x08BCEF70>: Failed to establish a new connection: [Errno 11001] getaddrinfo failed'))\n",
      "collecting... 21694413\n"
     ]
    }
   ],
   "source": [
    "# populate existing user_ids\n",
    "records = db['followers']\n",
    "populated_documents = records.find()\n",
    "populated_user_ids = []\n",
    "for document in populated_documents:\n",
    "    populated_user_ids.append(document['user_id'])\n",
    "for user_id in ROOT_USERS:\n",
    "    if user_id not in populated_user_ids:\n",
    "        try:\n",
    "            records = db['followers']               \n",
    "            records.insert_one({'user_id' : user_id, 'followers' : []})\n",
    "            try:\n",
    "                print('collecting...', user_id)\n",
    "                for follower in tweepy.Cursor(api.followers_ids, user_id = user_id).items(10000000):\n",
    "                    records.update_one({'user_id' : user_id}, {'$push' : {'followers' : follower}})\n",
    "#                     print(follower)\n",
    "            except tweepy.TweepError as e:\n",
    "                if 'Failed to send request:' in e.reason:\n",
    "                    print('Time out error caught.', e)\n",
    "                    time.sleep(180)\n",
    "                    continue\n",
    "        except Exception as e:\n",
    "            print(e, ' OR Connection failed')\n",
    "            time.sleep(180)\n",
    "            continue"
   ]
  }
 ],
 "metadata": {
  "kernelspec": {
   "display_name": "Python 3",
   "language": "python",
   "name": "python3"
  },
  "language_info": {
   "codemirror_mode": {
    "name": "ipython",
    "version": 3
   },
   "file_extension": ".py",
   "mimetype": "text/x-python",
   "name": "python",
   "nbconvert_exporter": "python",
   "pygments_lexer": "ipython3",
   "version": "3.7.6"
  }
 },
 "nbformat": 4,
 "nbformat_minor": 4
}
