{
 "cells": [
  {
   "cell_type": "code",
   "execution_count": 1,
   "metadata": {},
   "outputs": [],
   "source": [
    "from pymongo import MongoClient\n",
    "import glob\n",
    "import json"
   ]
  },
  {
   "cell_type": "code",
   "execution_count": 2,
   "metadata": {},
   "outputs": [],
   "source": [
    "# client = MongoClient('mongodb+srv://user:user@cluster0.ard5c.mongodb.net/test')\n",
    "client = MongoClient('mongodb://localhost:27017/')"
   ]
  },
  {
   "cell_type": "code",
   "execution_count": 3,
   "metadata": {},
   "outputs": [],
   "source": [
    "db = client.get_database('tweets')"
   ]
  },
  {
   "cell_type": "code",
   "execution_count": 4,
   "metadata": {},
   "outputs": [
    {
     "name": "stdout",
     "output_type": "stream",
     "text": [
      "nlp-dev\n"
     ]
    }
   ],
   "source": [
    "#### API Client\n",
    "\n",
    "import os\n",
    "print (os.environ['CONDA_DEFAULT_ENV'])\n",
    "\n",
    "import tweepy\n",
    "import webbrowser\n",
    "import time\n",
    "import pandas as pd\n",
    "import csv\n",
    "import json\n",
    "import requests\n",
    "\n",
    "# Chandima\n",
    "\n",
    "consumer_key = \"zsRsKjUByLghpmqnFfs8SdHqU\"\n",
    "consumer_secret = \"D1uISrpSNWtnNTsfvEVYTMDWZ0vwNYHCeQtPpq3FuTvbEqICcu\"\n",
    "\n",
    "access_token = \"254956599-RvNGcNu7CX7U5JlJdH3OOk7PQa8zrLXihdWBGHoI\"\n",
    "token_secret = \"RZEABGGdYBissPSxWK0n618z5FFi4B8PHHavPKKjp128T\""
   ]
  },
  {
   "cell_type": "code",
   "execution_count": 5,
   "metadata": {},
   "outputs": [],
   "source": [
    "# Authenticate to Twitter\n",
    "try:\n",
    "    auth = tweepy.OAuthHandler(consumer_key, consumer_secret)\n",
    "    auth.set_access_token(access_token, token_secret) \n",
    "except tweepy.TweepError as e:\n",
    "    print(e)\n",
    "    \n",
    "\n",
    "# Create API object\n",
    "api = tweepy.API(auth, wait_on_rate_limit=True,\n",
    "    wait_on_rate_limit_notify=True)"
   ]
  },
  {
   "cell_type": "code",
   "execution_count": 6,
   "metadata": {
    "scrolled": true,
    "tags": []
   },
   "outputs": [],
   "source": [
    "# # Group tweets by root tweet id (grater tha 200 retweets)\n",
    "# # Update followers list for each user \n",
    "\n",
    "# for rating_type in ['false']:\n",
    "#     for i in range(2,3):\n",
    "#         flag = True\n",
    "#         while flag:\n",
    "#             try:\n",
    "#                 cascade_root_user_ids = set()\n",
    "#                 # collection name\n",
    "#                 COLLECTION_NAME = 'data_{}_{}'.format(rating_type, i)\n",
    "#                 print(COLLECTION_NAME, 'trying to collect...')\n",
    "                \n",
    "#                 # populate existing user_ids\n",
    "#                 records = db['followers']\n",
    "#                 populated_documents = records.find()\n",
    "#                 populated_user_ids = []\n",
    "#                 for document in populated_documents:\n",
    "#                     populated_user_ids.append(document['user_id'])\n",
    "#                 print('Initalizing population...')\n",
    "                \n",
    "#                 records = db[COLLECTION_NAME]\n",
    "#                 cursor = records.find({'retweeted_status.retweet_count' : { '$gt' :200 } }, batch_size = 10)\n",
    "#                 for record in cursor:\n",
    "#                     user_id = record['user']['id']\n",
    "#                     if user_id not in populated_user_ids:\n",
    "#                         try:\n",
    "#                             cascade_root_user_ids.add(record['retweeted_status']['id'])\n",
    "#                             records = db['followers']               \n",
    "#                             records.insert_one({'user_id' : user_id, 'followers' : []})\n",
    "#                             try:\n",
    "#                                 print('collecting...', user_id)\n",
    "#                                 for follower in tweepy.Cursor(api.followers_ids, user_id = user_id).items(10000000):\n",
    "#                                     records.update_one({'user_id' : user_id}, {'$push' : {'followers' : follower}})\n",
    "#                             except tweepy.TweepError as e:\n",
    "#                                 if 'Failed to send request:' in e.reason:\n",
    "#                                     print('Time out error caught.', e.reason)\n",
    "#                                     time.sleep(180)\n",
    "#                                     continue\n",
    "#                         except (AttributeError, KeyError) as e:\n",
    "#                             print('AttributeError, KeyError failed')\n",
    "#                             continue\n",
    "#                 cursor = records.find({'retweeted_status.retweet_count' : { '$gt' :200 } }, batch_size = 10)\n",
    "#                 user_ids = list(record['user']['id'] for record in cursor )\n",
    "#                 print(type(user_ids), len(user_ids))\n",
    "#                 print(type(populated_user_ids), len(populated_user_ids))\n",
    "#                 if set(user_ids).issubset(set(populated_user_ids)):\n",
    "#                     flag = False\n",
    "#             except Exception as e:\n",
    "#                 print(e, ' OR Connection failed')\n",
    "#                 time.sleep(180)\n",
    "#                 continue"
   ]
  },
  {
   "cell_type": "code",
   "execution_count": 7,
   "metadata": {},
   "outputs": [],
   "source": [
    "# records = db['followers']\n",
    "# cursor = records.find().sort('_id',-1)\n",
    "# uncomplete_users = []\n",
    "# for record in cursor[:3]:\n",
    "#         print(record['user_id'])\n",
    "#         uncomplete_users.append(record['user_id'])"
   ]
  },
  {
   "cell_type": "code",
   "execution_count": 8,
   "metadata": {},
   "outputs": [],
   "source": [
    "# for doc in db['followers'].find({'user_id' : {'$in' : c}}):\n",
    "#     print(doc)"
   ]
  },
  {
   "cell_type": "code",
   "execution_count": 9,
   "metadata": {},
   "outputs": [],
   "source": [
    "ROOT_USERS = [803045912771723264, 1300414125894438912, 1237165957, 32283017, 701725963, 328440716, 907956112619577345, 896466491587080194, 880087618779848705, 1390669327, 756825355, 1727374842, 262491413, 549326614, 15755669, 21246105, 542962969, 18536347, 1070179749106876417, 3904453280, 1917731, 18649764, 16343974, 15615783, 1194649158856192001, 277261996, 34371118, 801080366, 14085040, 3222921301, 20333234, 2502895924, 30937910, 1356295552556822529, 1204616867987492870, 14294848, 1011409003170189312, 1570180292, 116003781, 540458181, 202543176, 1200551688911765504, 838372548156993541, 40601552, 20097362, 115563859, 1134635157049270272, 23818581, 14216661, 27202261, 18742360, 48089305, 1234977700198174721, 821928011939323904, 822501672018706434, 50626909, 337808606, 396158429, 59794400, 31359323, 1139189085241794562, 55260264, 820795826893180928, 4884088424, 1324724819716308992, 16012783, 64643056, 2371830000, 15535860, 1341150450394017792, 312149882,14294848, 3620255296, 1258193558953172992, 226926116, 1254877783622324224, 700937781267156992, 1491161642, 1165651610, 886339379056259072, 1247780339130368000, 1378043127232135169, 3230908953, 987306324932419584,600515073, 1356494984619327488, 32422915, 39453212, 819300029814947851, 116435488, 44389414, 986750503, 17372204, 156464691, 945823101589360641, 15438913, 35697740, 180810321, 1186291871921987584, 1129807762714763264, 30271065, 3331413095, 13120642, 380648579, 793315976, 2426189960, 32627341, 1166419406685188101, 44728980, 20716703, 33569444, 836126888, 1356084128056102917, 879324929669443584, 18266825, 927513257946083329, 63668427, 65666255, 2827042006, 407754462, 22274790, 1328778984, 19025138, 144367359, 4799680255, 1005882189752557573, 29118232, 2492545837, 19897138, 731164907870261248, 239343419, 18860860, 15448383, 14294848, 933325543180767232, 1022188086283960320, 55118669, 8362832, 210946385, 1377212711541514244, 22240612, 4928311139, 2282930023, 16746858, 1241031653318963200, 64302962, 2234067829, 1063040541141725184, 63362429, 2831137675, 3130569627, 15872418, 278077347, 3122243506, 216759733, 3026289081, 472122299, 825884820375011330, 121482708, 102098902, 1131352537, 726557224860966912, 3327890915, 4876193261, 410100725, 905355452988366854]"
   ]
  },
  {
   "cell_type": "code",
   "execution_count": null,
   "metadata": {
    "tags": []
   },
   "outputs": [
    {
     "name": "stdout",
     "output_type": "stream",
     "text": [
      "collecting... 549326614\n",
      "collecting... 15755669\n",
      "Time out error caught. Failed to send request: HTTPSConnectionPool(host='api.twitter.com', port=443): Max retries exceeded with url: /1.1/followers/ids.json?cursor=1594969719203039758&user_id=15755669 (Caused by NewConnectionError('<urllib3.connection.VerifiedHTTPSConnection object at 0x09270DB0>: Failed to establish a new connection: [Errno 11001] getaddrinfo failed'))\n",
      "collecting... 21246105\n",
      "Time out error caught. Failed to send request: HTTPSConnectionPool(host='api.twitter.com', port=443): Max retries exceeded with url: /1.1/followers/ids.json?cursor=-1&user_id=21246105 (Caused by NewConnectionError('<urllib3.connection.VerifiedHTTPSConnection object at 0x09270030>: Failed to establish a new connection: [Errno 11001] getaddrinfo failed'))\n",
      "collecting... 542962969\n",
      "Time out error caught. Failed to send request: HTTPSConnectionPool(host='api.twitter.com', port=443): Max retries exceeded with url: /1.1/followers/ids.json?cursor=-1&user_id=542962969 (Caused by NewConnectionError('<urllib3.connection.VerifiedHTTPSConnection object at 0x09270490>: Failed to establish a new connection: [Errno 11001] getaddrinfo failed'))\n",
      "collecting... 18536347\n",
      "Time out error caught. Failed to send request: HTTPSConnectionPool(host='api.twitter.com', port=443): Max retries exceeded with url: /1.1/followers/ids.json?cursor=-1&user_id=18536347 (Caused by NewConnectionError('<urllib3.connection.VerifiedHTTPSConnection object at 0x090F8EB0>: Failed to establish a new connection: [Errno 11001] getaddrinfo failed'))\n",
      "collecting... 1070179749106876417\n",
      "Time out error caught. Failed to send request: HTTPSConnectionPool(host='api.twitter.com', port=443): Max retries exceeded with url: /1.1/followers/ids.json?cursor=-1&user_id=1070179749106876417 (Caused by NewConnectionError('<urllib3.connection.VerifiedHTTPSConnection object at 0x09270E70>: Failed to establish a new connection: [Errno 11001] getaddrinfo failed'))\n",
      "collecting... 3904453280\n",
      "Time out error caught. Failed to send request: HTTPSConnectionPool(host='api.twitter.com', port=443): Max retries exceeded with url: /1.1/followers/ids.json?cursor=-1&user_id=3904453280 (Caused by NewConnectionError('<urllib3.connection.VerifiedHTTPSConnection object at 0x09270CD0>: Failed to establish a new connection: [Errno 11001] getaddrinfo failed'))\n",
      "collecting... 1917731\n",
      "Time out error caught. Failed to send request: HTTPSConnectionPool(host='api.twitter.com', port=443): Max retries exceeded with url: /1.1/followers/ids.json?cursor=-1&user_id=1917731 (Caused by NewConnectionError('<urllib3.connection.VerifiedHTTPSConnection object at 0x092706F0>: Failed to establish a new connection: [Errno 11001] getaddrinfo failed'))\n",
      "collecting... 18649764\n",
      "Time out error caught. Failed to send request: HTTPSConnectionPool(host='api.twitter.com', port=443): Max retries exceeded with url: /1.1/followers/ids.json?cursor=-1&user_id=18649764 (Caused by NewConnectionError('<urllib3.connection.VerifiedHTTPSConnection object at 0x092707F0>: Failed to establish a new connection: [Errno 11001] getaddrinfo failed'))\n",
      "collecting... 16343974\n",
      "Time out error caught. Failed to send request: HTTPSConnectionPool(host='api.twitter.com', port=443): Max retries exceeded with url: /1.1/followers/ids.json?cursor=-1&user_id=16343974 (Caused by NewConnectionError('<urllib3.connection.VerifiedHTTPSConnection object at 0x09270610>: Failed to establish a new connection: [Errno 11001] getaddrinfo failed'))\n",
      "collecting... 15615783\n",
      "Time out error caught. Failed to send request: HTTPSConnectionPool(host='api.twitter.com', port=443): Max retries exceeded with url: /1.1/followers/ids.json?cursor=-1&user_id=15615783 (Caused by NewConnectionError('<urllib3.connection.VerifiedHTTPSConnection object at 0x09270810>: Failed to establish a new connection: [Errno 11001] getaddrinfo failed'))\n",
      "collecting... 1194649158856192001\n",
      "Time out error caught. Failed to send request: HTTPSConnectionPool(host='api.twitter.com', port=443): Max retries exceeded with url: /1.1/followers/ids.json?cursor=-1&user_id=1194649158856192001 (Caused by NewConnectionError('<urllib3.connection.VerifiedHTTPSConnection object at 0x0591C2F0>: Failed to establish a new connection: [Errno 11001] getaddrinfo failed'))\n",
      "collecting... 277261996\n",
      "Time out error caught. Failed to send request: HTTPSConnectionPool(host='api.twitter.com', port=443): Max retries exceeded with url: /1.1/followers/ids.json?cursor=-1&user_id=277261996 (Caused by NewConnectionError('<urllib3.connection.VerifiedHTTPSConnection object at 0x05EE59D0>: Failed to establish a new connection: [Errno 11001] getaddrinfo failed'))\n",
      "collecting... 34371118\n",
      "Time out error caught. Failed to send request: HTTPSConnectionPool(host='api.twitter.com', port=443): Max retries exceeded with url: /1.1/followers/ids.json?cursor=-1&user_id=34371118 (Caused by NewConnectionError('<urllib3.connection.VerifiedHTTPSConnection object at 0x07E2EFD0>: Failed to establish a new connection: [Errno 11001] getaddrinfo failed'))\n",
      "collecting... 801080366\n",
      "Time out error caught. Failed to send request: HTTPSConnectionPool(host='api.twitter.com', port=443): Max retries exceeded with url: /1.1/followers/ids.json?cursor=-1&user_id=801080366 (Caused by NewConnectionError('<urllib3.connection.VerifiedHTTPSConnection object at 0x07E2ED50>: Failed to establish a new connection: [Errno 11001] getaddrinfo failed'))\n",
      "collecting... 14085040\n",
      "Time out error caught. Failed to send request: HTTPSConnectionPool(host='api.twitter.com', port=443): Max retries exceeded with url: /1.1/followers/ids.json?cursor=-1&user_id=14085040 (Caused by NewConnectionError('<urllib3.connection.VerifiedHTTPSConnection object at 0x05FF1070>: Failed to establish a new connection: [Errno 11001] getaddrinfo failed'))\n",
      "collecting... 3222921301\n",
      "Time out error caught. Failed to send request: HTTPSConnectionPool(host='api.twitter.com', port=443): Max retries exceeded with url: /1.1/followers/ids.json?cursor=-1&user_id=3222921301 (Caused by NewConnectionError('<urllib3.connection.VerifiedHTTPSConnection object at 0x05F2EDD0>: Failed to establish a new connection: [Errno 11001] getaddrinfo failed'))\n",
      "collecting... 20333234\n",
      "Time out error caught. Failed to send request: HTTPSConnectionPool(host='api.twitter.com', port=443): Max retries exceeded with url: /1.1/followers/ids.json?cursor=-1&user_id=20333234 (Caused by NewConnectionError('<urllib3.connection.VerifiedHTTPSConnection object at 0x05F2EB50>: Failed to establish a new connection: [Errno 11001] getaddrinfo failed'))\n",
      "collecting... 2502895924\n",
      "Time out error caught. Failed to send request: HTTPSConnectionPool(host='api.twitter.com', port=443): Max retries exceeded with url: /1.1/followers/ids.json?cursor=-1&user_id=2502895924 (Caused by NewConnectionError('<urllib3.connection.VerifiedHTTPSConnection object at 0x07149CB0>: Failed to establish a new connection: [Errno 11001] getaddrinfo failed'))\n",
      "collecting... 30937910\n",
      "Time out error caught. Failed to send request: HTTPSConnectionPool(host='api.twitter.com', port=443): Max retries exceeded with url: /1.1/followers/ids.json?cursor=-1&user_id=30937910 (Caused by NewConnectionError('<urllib3.connection.VerifiedHTTPSConnection object at 0x09270EF0>: Failed to establish a new connection: [Errno 11001] getaddrinfo failed'))\n",
      "collecting... 1356295552556822529\n",
      "Time out error caught. Failed to send request: HTTPSConnectionPool(host='api.twitter.com', port=443): Max retries exceeded with url: /1.1/followers/ids.json?cursor=-1&user_id=1356295552556822529 (Caused by NewConnectionError('<urllib3.connection.VerifiedHTTPSConnection object at 0x092704F0>: Failed to establish a new connection: [Errno 11001] getaddrinfo failed'))\n",
      "collecting... 1204616867987492870\n",
      "Time out error caught. Failed to send request: HTTPSConnectionPool(host='api.twitter.com', port=443): Max retries exceeded with url: /1.1/followers/ids.json?cursor=-1&user_id=1204616867987492870 (Caused by NewConnectionError('<urllib3.connection.VerifiedHTTPSConnection object at 0x07C158D0>: Failed to establish a new connection: [Errno 11001] getaddrinfo failed'))\n",
      "collecting... 14294848\n",
      "Time out error caught. Failed to send request: HTTPSConnectionPool(host='api.twitter.com', port=443): Max retries exceeded with url: /1.1/followers/ids.json?cursor=-1&user_id=14294848 (Caused by NewConnectionError('<urllib3.connection.VerifiedHTTPSConnection object at 0x07C15830>: Failed to establish a new connection: [Errno 11001] getaddrinfo failed'))\n",
      "collecting... 1011409003170189312\n",
      "Time out error caught. Failed to send request: HTTPSConnectionPool(host='api.twitter.com', port=443): Max retries exceeded with url: /1.1/followers/ids.json?cursor=-1&user_id=1011409003170189312 (Caused by NewConnectionError('<urllib3.connection.VerifiedHTTPSConnection object at 0x07C15830>: Failed to establish a new connection: [Errno 11001] getaddrinfo failed'))\n",
      "collecting... 1570180292\n",
      "Time out error caught. Failed to send request: HTTPSConnectionPool(host='api.twitter.com', port=443): Max retries exceeded with url: /1.1/followers/ids.json?cursor=-1&user_id=1570180292 (Caused by NewConnectionError('<urllib3.connection.VerifiedHTTPSConnection object at 0x09270F70>: Failed to establish a new connection: [Errno 11001] getaddrinfo failed'))\n",
      "collecting... 116003781\n",
      "Time out error caught. Failed to send request: HTTPSConnectionPool(host='api.twitter.com', port=443): Max retries exceeded with url: /1.1/followers/ids.json?cursor=-1&user_id=116003781 (Caused by NewConnectionError('<urllib3.connection.VerifiedHTTPSConnection object at 0x090F8610>: Failed to establish a new connection: [Errno 11001] getaddrinfo failed'))\n",
      "collecting... 540458181\n",
      "Time out error caught. Failed to send request: HTTPSConnectionPool(host='api.twitter.com', port=443): Max retries exceeded with url: /1.1/followers/ids.json?cursor=-1&user_id=540458181 (Caused by NewConnectionError('<urllib3.connection.VerifiedHTTPSConnection object at 0x090F8590>: Failed to establish a new connection: [Errno 11001] getaddrinfo failed'))\n",
      "collecting... 202543176\n",
      "Time out error caught. Failed to send request: HTTPSConnectionPool(host='api.twitter.com', port=443): Max retries exceeded with url: /1.1/followers/ids.json?cursor=-1&user_id=202543176 (Caused by NewConnectionError('<urllib3.connection.VerifiedHTTPSConnection object at 0x09270F70>: Failed to establish a new connection: [Errno 11001] getaddrinfo failed'))\n",
      "collecting... 1200551688911765504\n",
      "Time out error caught. Failed to send request: HTTPSConnectionPool(host='api.twitter.com', port=443): Max retries exceeded with url: /1.1/followers/ids.json?cursor=-1&user_id=1200551688911765504 (Caused by NewConnectionError('<urllib3.connection.VerifiedHTTPSConnection object at 0x09270FB0>: Failed to establish a new connection: [Errno 11001] getaddrinfo failed'))\n",
      "collecting... 838372548156993541\n",
      "Time out error caught. Failed to send request: HTTPSConnectionPool(host='api.twitter.com', port=443): Max retries exceeded with url: /1.1/followers/ids.json?cursor=-1&user_id=838372548156993541 (Caused by NewConnectionError('<urllib3.connection.VerifiedHTTPSConnection object at 0x056BEB10>: Failed to establish a new connection: [Errno 11001] getaddrinfo failed'))\n",
      "collecting... 20097362\n",
      "Time out error caught. Failed to send request: HTTPSConnectionPool(host='api.twitter.com', port=443): Max retries exceeded with url: /1.1/followers/ids.json?cursor=-1&user_id=20097362 (Caused by NewConnectionError('<urllib3.connection.VerifiedHTTPSConnection object at 0x09270670>: Failed to establish a new connection: [Errno 11001] getaddrinfo failed'))\n",
      "collecting... 115563859\n",
      "Time out error caught. Failed to send request: HTTPSConnectionPool(host='api.twitter.com', port=443): Max retries exceeded with url: /1.1/followers/ids.json?cursor=-1&user_id=115563859 (Caused by NewConnectionError('<urllib3.connection.VerifiedHTTPSConnection object at 0x09270BB0>: Failed to establish a new connection: [Errno 11001] getaddrinfo failed'))\n",
      "collecting... 1134635157049270272\n",
      "Time out error caught. Failed to send request: HTTPSConnectionPool(host='api.twitter.com', port=443): Max retries exceeded with url: /1.1/followers/ids.json?cursor=-1&user_id=1134635157049270272 (Caused by NewConnectionError('<urllib3.connection.VerifiedHTTPSConnection object at 0x056C4250>: Failed to establish a new connection: [Errno 11001] getaddrinfo failed'))\n",
      "collecting... 23818581\n",
      "Time out error caught. Failed to send request: HTTPSConnectionPool(host='api.twitter.com', port=443): Max retries exceeded with url: /1.1/followers/ids.json?cursor=-1&user_id=23818581 (Caused by NewConnectionError('<urllib3.connection.VerifiedHTTPSConnection object at 0x05FF1070>: Failed to establish a new connection: [Errno 11001] getaddrinfo failed'))\n",
      "collecting... 14216661\n",
      "Time out error caught. Failed to send request: HTTPSConnectionPool(host='api.twitter.com', port=443): Max retries exceeded with url: /1.1/followers/ids.json?cursor=-1&user_id=14216661 (Caused by NewConnectionError('<urllib3.connection.VerifiedHTTPSConnection object at 0x066BC770>: Failed to establish a new connection: [Errno 11001] getaddrinfo failed'))\n",
      "collecting... 27202261\n",
      "Time out error caught. Failed to send request: HTTPSConnectionPool(host='api.twitter.com', port=443): Max retries exceeded with url: /1.1/followers/ids.json?cursor=-1&user_id=27202261 (Caused by NewConnectionError('<urllib3.connection.VerifiedHTTPSConnection object at 0x090F8390>: Failed to establish a new connection: [Errno 11001] getaddrinfo failed'))\n",
      "collecting... 18742360\n",
      "Time out error caught. Failed to send request: HTTPSConnectionPool(host='api.twitter.com', port=443): Max retries exceeded with url: /1.1/followers/ids.json?cursor=-1&user_id=18742360 (Caused by NewConnectionError('<urllib3.connection.VerifiedHTTPSConnection object at 0x05929070>: Failed to establish a new connection: [Errno 11001] getaddrinfo failed'))\n",
      "collecting... 48089305\n",
      "Time out error caught. Failed to send request: HTTPSConnectionPool(host='api.twitter.com', port=443): Max retries exceeded with url: /1.1/followers/ids.json?cursor=-1&user_id=48089305 (Caused by NewConnectionError('<urllib3.connection.VerifiedHTTPSConnection object at 0x0926D0B0>: Failed to establish a new connection: [Errno 11001] getaddrinfo failed'))\n",
      "collecting... 1234977700198174721\n",
      "Time out error caught. Failed to send request: HTTPSConnectionPool(host='api.twitter.com', port=443): Max retries exceeded with url: /1.1/followers/ids.json?cursor=-1&user_id=1234977700198174721 (Caused by NewConnectionError('<urllib3.connection.VerifiedHTTPSConnection object at 0x07E2EEF0>: Failed to establish a new connection: [Errno 11001] getaddrinfo failed'))\n",
      "collecting... 821928011939323904\n",
      "Time out error caught. Failed to send request: HTTPSConnectionPool(host='api.twitter.com', port=443): Max retries exceeded with url: /1.1/followers/ids.json?cursor=-1&user_id=821928011939323904 (Caused by NewConnectionError('<urllib3.connection.VerifiedHTTPSConnection object at 0x07E1D310>: Failed to establish a new connection: [Errno 11001] getaddrinfo failed'))\n",
      "collecting... 822501672018706434\n",
      "Time out error caught. Failed to send request: HTTPSConnectionPool(host='api.twitter.com', port=443): Max retries exceeded with url: /1.1/followers/ids.json?cursor=-1&user_id=822501672018706434 (Caused by NewConnectionError('<urllib3.connection.VerifiedHTTPSConnection object at 0x071496D0>: Failed to establish a new connection: [Errno 11001] getaddrinfo failed'))\n",
      "collecting... 50626909\n",
      "Time out error caught. Failed to send request: HTTPSConnectionPool(host='api.twitter.com', port=443): Max retries exceeded with url: /1.1/followers/ids.json?cursor=-1&user_id=50626909 (Caused by NewConnectionError('<urllib3.connection.VerifiedHTTPSConnection object at 0x07D0E930>: Failed to establish a new connection: [Errno 11001] getaddrinfo failed'))\n",
      "collecting... 337808606\n",
      "Time out error caught. Failed to send request: HTTPSConnectionPool(host='api.twitter.com', port=443): Max retries exceeded with url: /1.1/followers/ids.json?cursor=-1&user_id=337808606 (Caused by NewConnectionError('<urllib3.connection.VerifiedHTTPSConnection object at 0x09270690>: Failed to establish a new connection: [Errno 11001] getaddrinfo failed'))\n",
      "collecting... 396158429\n",
      "Time out error caught. Failed to send request: HTTPSConnectionPool(host='api.twitter.com', port=443): Max retries exceeded with url: /1.1/followers/ids.json?cursor=-1&user_id=396158429 (Caused by NewConnectionError('<urllib3.connection.VerifiedHTTPSConnection object at 0x090F8210>: Failed to establish a new connection: [Errno 11001] getaddrinfo failed'))\n",
      "collecting... 59794400\n",
      "Time out error caught. Failed to send request: HTTPSConnectionPool(host='api.twitter.com', port=443): Max retries exceeded with url: /1.1/followers/ids.json?cursor=-1&user_id=59794400 (Caused by NewConnectionError('<urllib3.connection.VerifiedHTTPSConnection object at 0x07E2EDB0>: Failed to establish a new connection: [Errno 11001] getaddrinfo failed'))\n",
      "collecting... 31359323\n",
      "Time out error caught. Failed to send request: HTTPSConnectionPool(host='api.twitter.com', port=443): Max retries exceeded with url: /1.1/followers/ids.json?cursor=-1&user_id=31359323 (Caused by NewConnectionError('<urllib3.connection.VerifiedHTTPSConnection object at 0x056BBD70>: Failed to establish a new connection: [Errno 11001] getaddrinfo failed'))\n",
      "collecting... 1139189085241794562\n",
      "Time out error caught. Failed to send request: HTTPSConnectionPool(host='api.twitter.com', port=443): Max retries exceeded with url: /1.1/followers/ids.json?cursor=-1&user_id=1139189085241794562 (Caused by NewConnectionError('<urllib3.connection.VerifiedHTTPSConnection object at 0x09270450>: Failed to establish a new connection: [Errno 11001] getaddrinfo failed'))\n",
      "collecting... 55260264\n",
      "Time out error caught. Failed to send request: HTTPSConnectionPool(host='api.twitter.com', port=443): Max retries exceeded with url: /1.1/followers/ids.json?cursor=-1&user_id=55260264 (Caused by NewConnectionError('<urllib3.connection.VerifiedHTTPSConnection object at 0x09270D70>: Failed to establish a new connection: [Errno 11001] getaddrinfo failed'))\n",
      "collecting... 820795826893180928\n",
      "Time out error caught. Failed to send request: HTTPSConnectionPool(host='api.twitter.com', port=443): Max retries exceeded with url: /1.1/followers/ids.json?cursor=-1&user_id=820795826893180928 (Caused by NewConnectionError('<urllib3.connection.VerifiedHTTPSConnection object at 0x0926D130>: Failed to establish a new connection: [Errno 11001] getaddrinfo failed'))\n",
      "collecting... 4884088424\n",
      "Time out error caught. Failed to send request: HTTPSConnectionPool(host='api.twitter.com', port=443): Max retries exceeded with url: /1.1/followers/ids.json?cursor=-1&user_id=4884088424 (Caused by NewConnectionError('<urllib3.connection.VerifiedHTTPSConnection object at 0x09270BD0>: Failed to establish a new connection: [Errno 11001] getaddrinfo failed'))\n",
      "collecting... 1324724819716308992\n",
      "Time out error caught. Failed to send request: HTTPSConnectionPool(host='api.twitter.com', port=443): Max retries exceeded with url: /1.1/followers/ids.json?cursor=-1&user_id=1324724819716308992 (Caused by NewConnectionError('<urllib3.connection.VerifiedHTTPSConnection object at 0x09270830>: Failed to establish a new connection: [Errno 11001] getaddrinfo failed'))\n",
      "collecting... 16012783\n",
      "Time out error caught. Failed to send request: HTTPSConnectionPool(host='api.twitter.com', port=443): Max retries exceeded with url: /1.1/followers/ids.json?cursor=-1&user_id=16012783 (Caused by NewConnectionError('<urllib3.connection.VerifiedHTTPSConnection object at 0x09270410>: Failed to establish a new connection: [Errno 11001] getaddrinfo failed'))\n",
      "collecting... 64643056\n",
      "Time out error caught. Failed to send request: HTTPSConnectionPool(host='api.twitter.com', port=443): Max retries exceeded with url: /1.1/followers/ids.json?cursor=-1&user_id=64643056 (Caused by NewConnectionError('<urllib3.connection.VerifiedHTTPSConnection object at 0x09270BB0>: Failed to establish a new connection: [Errno 11001] getaddrinfo failed'))\n",
      "collecting... 2371830000\n",
      "Time out error caught. Failed to send request: HTTPSConnectionPool(host='api.twitter.com', port=443): Max retries exceeded with url: /1.1/followers/ids.json?cursor=-1&user_id=2371830000 (Caused by NewConnectionError('<urllib3.connection.VerifiedHTTPSConnection object at 0x0591C2F0>: Failed to establish a new connection: [Errno 11001] getaddrinfo failed'))\n",
      "collecting... 15535860\n",
      "Time out error caught. Failed to send request: HTTPSConnectionPool(host='api.twitter.com', port=443): Max retries exceeded with url: /1.1/followers/ids.json?cursor=-1&user_id=15535860 (Caused by NewConnectionError('<urllib3.connection.VerifiedHTTPSConnection object at 0x05FF1070>: Failed to establish a new connection: [Errno 11001] getaddrinfo failed'))\n",
      "collecting... 1341150450394017792\n",
      "Time out error caught. Failed to send request: HTTPSConnectionPool(host='api.twitter.com', port=443): Max retries exceeded with url: /1.1/followers/ids.json?cursor=-1&user_id=1341150450394017792 (Caused by NewConnectionError('<urllib3.connection.VerifiedHTTPSConnection object at 0x046EE750>: Failed to establish a new connection: [Errno 11001] getaddrinfo failed'))\n",
      "collecting... 312149882\n",
      "Time out error caught. Failed to send request: HTTPSConnectionPool(host='api.twitter.com', port=443): Max retries exceeded with url: /1.1/followers/ids.json?cursor=-1&user_id=312149882 (Caused by NewConnectionError('<urllib3.connection.VerifiedHTTPSConnection object at 0x07149B90>: Failed to establish a new connection: [Errno 11001] getaddrinfo failed'))\n",
      "collecting... 14294848\n",
      "Time out error caught. Failed to send request: HTTPSConnectionPool(host='api.twitter.com', port=443): Max retries exceeded with url: /1.1/followers/ids.json?cursor=-1&user_id=14294848 (Caused by NewConnectionError('<urllib3.connection.VerifiedHTTPSConnection object at 0x056BE9F0>: Failed to establish a new connection: [Errno 11001] getaddrinfo failed'))\n",
      "collecting... 3620255296\n",
      "Time out error caught. Failed to send request: HTTPSConnectionPool(host='api.twitter.com', port=443): Max retries exceeded with url: /1.1/followers/ids.json?cursor=-1&user_id=3620255296 (Caused by NewConnectionError('<urllib3.connection.VerifiedHTTPSConnection object at 0x0926D350>: Failed to establish a new connection: [Errno 11001] getaddrinfo failed'))\n",
      "collecting... 1258193558953172992\n",
      "Time out error caught. Failed to send request: HTTPSConnectionPool(host='api.twitter.com', port=443): Max retries exceeded with url: /1.1/followers/ids.json?cursor=-1&user_id=1258193558953172992 (Caused by NewConnectionError('<urllib3.connection.VerifiedHTTPSConnection object at 0x0926D5B0>: Failed to establish a new connection: [Errno 11001] getaddrinfo failed'))\n",
      "collecting... 226926116\n",
      "Time out error caught. Failed to send request: HTTPSConnectionPool(host='api.twitter.com', port=443): Max retries exceeded with url: /1.1/followers/ids.json?cursor=-1&user_id=226926116 (Caused by NewConnectionError('<urllib3.connection.VerifiedHTTPSConnection object at 0x090F8910>: Failed to establish a new connection: [Errno 11001] getaddrinfo failed'))\n",
      "collecting... 1254877783622324224\n",
      "Time out error caught. Failed to send request: HTTPSConnectionPool(host='api.twitter.com', port=443): Max retries exceeded with url: /1.1/followers/ids.json?cursor=-1&user_id=1254877783622324224 (Caused by NewConnectionError('<urllib3.connection.VerifiedHTTPSConnection object at 0x05929090>: Failed to establish a new connection: [Errno 11001] getaddrinfo failed'))\n",
      "collecting... 700937781267156992\n",
      "Time out error caught. Failed to send request: HTTPSConnectionPool(host='api.twitter.com', port=443): Max retries exceeded with url: /1.1/followers/ids.json?cursor=-1&user_id=700937781267156992 (Caused by NewConnectionError('<urllib3.connection.VerifiedHTTPSConnection object at 0x09270470>: Failed to establish a new connection: [Errno 11001] getaddrinfo failed'))\n",
      "collecting... 1491161642\n",
      "Time out error caught. Failed to send request: HTTPSConnectionPool(host='api.twitter.com', port=443): Max retries exceeded with url: /1.1/followers/ids.json?cursor=-1&user_id=1491161642 (Caused by NewConnectionError('<urllib3.connection.VerifiedHTTPSConnection object at 0x05929070>: Failed to establish a new connection: [Errno 11001] getaddrinfo failed'))\n",
      "collecting... 1165651610\n",
      "Time out error caught. Failed to send request: HTTPSConnectionPool(host='api.twitter.com', port=443): Max retries exceeded with url: /1.1/followers/ids.json?cursor=-1&user_id=1165651610 (Caused by NewConnectionError('<urllib3.connection.VerifiedHTTPSConnection object at 0x092701B0>: Failed to establish a new connection: [Errno 11001] getaddrinfo failed'))\n",
      "collecting... 886339379056259072\n",
      "Time out error caught. Failed to send request: HTTPSConnectionPool(host='api.twitter.com', port=443): Max retries exceeded with url: /1.1/followers/ids.json?cursor=-1&user_id=886339379056259072 (Caused by NewConnectionError('<urllib3.connection.VerifiedHTTPSConnection object at 0x07149CB0>: Failed to establish a new connection: [Errno 11001] getaddrinfo failed'))\n",
      "collecting... 1247780339130368000\n",
      "Time out error caught. Failed to send request: HTTPSConnectionPool(host='api.twitter.com', port=443): Max retries exceeded with url: /1.1/followers/ids.json?cursor=-1&user_id=1247780339130368000 (Caused by NewConnectionError('<urllib3.connection.VerifiedHTTPSConnection object at 0x09270C10>: Failed to establish a new connection: [Errno 11001] getaddrinfo failed'))\n",
      "collecting... 1378043127232135169\n",
      "Time out error caught. Failed to send request: HTTPSConnectionPool(host='api.twitter.com', port=443): Max retries exceeded with url: /1.1/followers/ids.json?cursor=-1&user_id=1378043127232135169 (Caused by NewConnectionError('<urllib3.connection.VerifiedHTTPSConnection object at 0x09270650>: Failed to establish a new connection: [Errno 11001] getaddrinfo failed'))\n",
      "collecting... 3230908953\n",
      "Time out error caught. Failed to send request: HTTPSConnectionPool(host='api.twitter.com', port=443): Max retries exceeded with url: /1.1/followers/ids.json?cursor=-1&user_id=3230908953 (Caused by NewConnectionError('<urllib3.connection.VerifiedHTTPSConnection object at 0x09270BD0>: Failed to establish a new connection: [Errno 11001] getaddrinfo failed'))\n",
      "collecting... 987306324932419584\n",
      "Time out error caught. Failed to send request: HTTPSConnectionPool(host='api.twitter.com', port=443): Max retries exceeded with url: /1.1/followers/ids.json?cursor=-1&user_id=987306324932419584 (Caused by NewConnectionError('<urllib3.connection.VerifiedHTTPSConnection object at 0x092709F0>: Failed to establish a new connection: [Errno 11001] getaddrinfo failed'))\n",
      "collecting... 600515073\n",
      "Time out error caught. Failed to send request: HTTPSConnectionPool(host='api.twitter.com', port=443): Max retries exceeded with url: /1.1/followers/ids.json?cursor=-1&user_id=600515073 (Caused by NewConnectionError('<urllib3.connection.VerifiedHTTPSConnection object at 0x0926D190>: Failed to establish a new connection: [Errno 11001] getaddrinfo failed'))\n",
      "collecting... 1356494984619327488\n",
      "Time out error caught. Failed to send request: HTTPSConnectionPool(host='api.twitter.com', port=443): Max retries exceeded with url: /1.1/followers/ids.json?cursor=-1&user_id=1356494984619327488 (Caused by NewConnectionError('<urllib3.connection.VerifiedHTTPSConnection object at 0x09270050>: Failed to establish a new connection: [Errno 11001] getaddrinfo failed'))\n",
      "collecting... 32422915\n",
      "Time out error caught. Failed to send request: HTTPSConnectionPool(host='api.twitter.com', port=443): Max retries exceeded with url: /1.1/followers/ids.json?cursor=-1&user_id=32422915 (Caused by NewConnectionError('<urllib3.connection.VerifiedHTTPSConnection object at 0x09270BD0>: Failed to establish a new connection: [Errno 11001] getaddrinfo failed'))\n",
      "collecting... 39453212\n",
      "Time out error caught. Failed to send request: HTTPSConnectionPool(host='api.twitter.com', port=443): Max retries exceeded with url: /1.1/followers/ids.json?cursor=-1&user_id=39453212 (Caused by NewConnectionError('<urllib3.connection.VerifiedHTTPSConnection object at 0x0591C050>: Failed to establish a new connection: [Errno 11001] getaddrinfo failed'))\n",
      "collecting... 819300029814947851\n",
      "Time out error caught. Failed to send request: HTTPSConnectionPool(host='api.twitter.com', port=443): Max retries exceeded with url: /1.1/followers/ids.json?cursor=-1&user_id=819300029814947851 (Caused by NewConnectionError('<urllib3.connection.VerifiedHTTPSConnection object at 0x05FF14D0>: Failed to establish a new connection: [Errno 11001] getaddrinfo failed'))\n",
      "collecting... 116435488\n",
      "Time out error caught. Failed to send request: HTTPSConnectionPool(host='api.twitter.com', port=443): Max retries exceeded with url: /1.1/followers/ids.json?cursor=-1&user_id=116435488 (Caused by NewConnectionError('<urllib3.connection.VerifiedHTTPSConnection object at 0x07E1D310>: Failed to establish a new connection: [Errno 11001] getaddrinfo failed'))\n",
      "collecting... 44389414\n",
      "Time out error caught. Failed to send request: HTTPSConnectionPool(host='api.twitter.com', port=443): Max retries exceeded with url: /1.1/followers/ids.json?cursor=-1&user_id=44389414 (Caused by NewConnectionError('<urllib3.connection.VerifiedHTTPSConnection object at 0x05929090>: Failed to establish a new connection: [Errno 11001] getaddrinfo failed'))\n",
      "collecting... 986750503\n",
      "Time out error caught. Failed to send request: HTTPSConnectionPool(host='api.twitter.com', port=443): Max retries exceeded with url: /1.1/followers/ids.json?cursor=-1&user_id=986750503 (Caused by NewConnectionError('<urllib3.connection.VerifiedHTTPSConnection object at 0x046EE750>: Failed to establish a new connection: [Errno 11001] getaddrinfo failed'))\n",
      "collecting... 17372204\n",
      "Time out error caught. Failed to send request: HTTPSConnectionPool(host='api.twitter.com', port=443): Max retries exceeded with url: /1.1/followers/ids.json?cursor=-1&user_id=17372204 (Caused by NewConnectionError('<urllib3.connection.VerifiedHTTPSConnection object at 0x056C4B10>: Failed to establish a new connection: [Errno 11001] getaddrinfo failed'))\n",
      "collecting... 156464691\n",
      "Time out error caught. Failed to send request: HTTPSConnectionPool(host='api.twitter.com', port=443): Max retries exceeded with url: /1.1/followers/ids.json?cursor=-1&user_id=156464691 (Caused by NewConnectionError('<urllib3.connection.VerifiedHTTPSConnection object at 0x0926D170>: Failed to establish a new connection: [Errno 11001] getaddrinfo failed'))\n",
      "collecting... 945823101589360641\n",
      "Time out error caught. Failed to send request: HTTPSConnectionPool(host='api.twitter.com', port=443): Max retries exceeded with url: /1.1/followers/ids.json?cursor=-1&user_id=945823101589360641 (Caused by NewConnectionError('<urllib3.connection.VerifiedHTTPSConnection object at 0x0926D0D0>: Failed to establish a new connection: [Errno 11001] getaddrinfo failed'))\n",
      "collecting... 15438913\n",
      "Time out error caught. Failed to send request: HTTPSConnectionPool(host='api.twitter.com', port=443): Max retries exceeded with url: /1.1/followers/ids.json?cursor=-1&user_id=15438913 (Caused by NewConnectionError('<urllib3.connection.VerifiedHTTPSConnection object at 0x090F8910>: Failed to establish a new connection: [Errno 11001] getaddrinfo failed'))\n",
      "collecting... 35697740\n",
      "Time out error caught. Failed to send request: HTTPSConnectionPool(host='api.twitter.com', port=443): Max retries exceeded with url: /1.1/followers/ids.json?cursor=-1&user_id=35697740 (Caused by NewConnectionError('<urllib3.connection.VerifiedHTTPSConnection object at 0x056C4550>: Failed to establish a new connection: [Errno 11001] getaddrinfo failed'))\n",
      "collecting... 180810321\n",
      "Time out error caught. Failed to send request: HTTPSConnectionPool(host='api.twitter.com', port=443): Max retries exceeded with url: /1.1/followers/ids.json?cursor=-1&user_id=180810321 (Caused by NewConnectionError('<urllib3.connection.VerifiedHTTPSConnection object at 0x07E2EBD0>: Failed to establish a new connection: [Errno 11001] getaddrinfo failed'))\n",
      "collecting... 1186291871921987584\n",
      "Time out error caught. Failed to send request: HTTPSConnectionPool(host='api.twitter.com', port=443): Max retries exceeded with url: /1.1/followers/ids.json?cursor=-1&user_id=1186291871921987584 (Caused by NewConnectionError('<urllib3.connection.VerifiedHTTPSConnection object at 0x05EE5AD0>: Failed to establish a new connection: [Errno 11001] getaddrinfo failed'))\n",
      "collecting... 1129807762714763264\n",
      "Time out error caught. Failed to send request: HTTPSConnectionPool(host='api.twitter.com', port=443): Max retries exceeded with url: /1.1/followers/ids.json?cursor=-1&user_id=1129807762714763264 (Caused by NewConnectionError('<urllib3.connection.VerifiedHTTPSConnection object at 0x09270730>: Failed to establish a new connection: [Errno 11001] getaddrinfo failed'))\n",
      "collecting... 30271065\n",
      "Time out error caught. Failed to send request: HTTPSConnectionPool(host='api.twitter.com', port=443): Max retries exceeded with url: /1.1/followers/ids.json?cursor=-1&user_id=30271065 (Caused by NewConnectionError('<urllib3.connection.VerifiedHTTPSConnection object at 0x09270D90>: Failed to establish a new connection: [Errno 11001] getaddrinfo failed'))\n",
      "collecting... 3331413095\n",
      "Time out error caught. Failed to send request: HTTPSConnectionPool(host='api.twitter.com', port=443): Max retries exceeded with url: /1.1/followers/ids.json?cursor=-1&user_id=3331413095 (Caused by NewConnectionError('<urllib3.connection.VerifiedHTTPSConnection object at 0x092703D0>: Failed to establish a new connection: [Errno 11001] getaddrinfo failed'))\n",
      "collecting... 13120642\n",
      "Time out error caught. Failed to send request: HTTPSConnectionPool(host='api.twitter.com', port=443): Max retries exceeded with url: /1.1/followers/ids.json?cursor=-1&user_id=13120642 (Caused by NewConnectionError('<urllib3.connection.VerifiedHTTPSConnection object at 0x09270FB0>: Failed to establish a new connection: [Errno 11001] getaddrinfo failed'))\n",
      "collecting... 380648579\n",
      "Time out error caught. Failed to send request: HTTPSConnectionPool(host='api.twitter.com', port=443): Max retries exceeded with url: /1.1/followers/ids.json?cursor=-1&user_id=380648579 (Caused by NewConnectionError('<urllib3.connection.VerifiedHTTPSConnection object at 0x09270D90>: Failed to establish a new connection: [Errno 11001] getaddrinfo failed'))\n",
      "collecting... 793315976\n",
      "Time out error caught. Failed to send request: HTTPSConnectionPool(host='api.twitter.com', port=443): Max retries exceeded with url: /1.1/followers/ids.json?cursor=-1&user_id=793315976 (Caused by NewConnectionError('<urllib3.connection.VerifiedHTTPSConnection object at 0x071496D0>: Failed to establish a new connection: [Errno 11001] getaddrinfo failed'))\n",
      "collecting... 2426189960\n",
      "Time out error caught. Failed to send request: HTTPSConnectionPool(host='api.twitter.com', port=443): Max retries exceeded with url: /1.1/followers/ids.json?cursor=-1&user_id=2426189960 (Caused by NewConnectionError('<urllib3.connection.VerifiedHTTPSConnection object at 0x0926DAF0>: Failed to establish a new connection: [Errno 11001] getaddrinfo failed'))\n",
      "collecting... 32627341\n",
      "Time out error caught. Failed to send request: HTTPSConnectionPool(host='api.twitter.com', port=443): Max retries exceeded with url: /1.1/followers/ids.json?cursor=-1&user_id=32627341 (Caused by NewConnectionError('<urllib3.connection.VerifiedHTTPSConnection object at 0x0591C2F0>: Failed to establish a new connection: [Errno 11001] getaddrinfo failed'))\n",
      "collecting... 1166419406685188101\n",
      "Time out error caught. Failed to send request: HTTPSConnectionPool(host='api.twitter.com', port=443): Max retries exceeded with url: /1.1/followers/ids.json?cursor=-1&user_id=1166419406685188101 (Caused by NewConnectionError('<urllib3.connection.VerifiedHTTPSConnection object at 0x092706F0>: Failed to establish a new connection: [Errno 11001] getaddrinfo failed'))\n",
      "collecting... 44728980\n",
      "Time out error caught. Failed to send request: HTTPSConnectionPool(host='api.twitter.com', port=443): Max retries exceeded with url: /1.1/followers/ids.json?cursor=-1&user_id=44728980 (Caused by NewConnectionError('<urllib3.connection.VerifiedHTTPSConnection object at 0x07C158D0>: Failed to establish a new connection: [Errno 11001] getaddrinfo failed'))\n",
      "collecting... 20716703\n",
      "Time out error caught. Failed to send request: HTTPSConnectionPool(host='api.twitter.com', port=443): Max retries exceeded with url: /1.1/followers/ids.json?cursor=-1&user_id=20716703 (Caused by NewConnectionError('<urllib3.connection.VerifiedHTTPSConnection object at 0x0591C2F0>: Failed to establish a new connection: [Errno 11001] getaddrinfo failed'))\n",
      "collecting... 33569444\n",
      "Time out error caught. Failed to send request: HTTPSConnectionPool(host='api.twitter.com', port=443): Max retries exceeded with url: /1.1/followers/ids.json?cursor=-1&user_id=33569444 (Caused by NewConnectionError('<urllib3.connection.VerifiedHTTPSConnection object at 0x092701D0>: Failed to establish a new connection: [Errno 11001] getaddrinfo failed'))\n",
      "collecting... 836126888\n",
      "Time out error caught. Failed to send request: HTTPSConnectionPool(host='api.twitter.com', port=443): Max retries exceeded with url: /1.1/followers/ids.json?cursor=-1&user_id=836126888 (Caused by NewConnectionError('<urllib3.connection.VerifiedHTTPSConnection object at 0x07E2EEF0>: Failed to establish a new connection: [Errno 11001] getaddrinfo failed'))\n",
      "collecting... 1356084128056102917\n",
      "Time out error caught. Failed to send request: HTTPSConnectionPool(host='api.twitter.com', port=443): Max retries exceeded with url: /1.1/followers/ids.json?cursor=-1&user_id=1356084128056102917 (Caused by NewConnectionError('<urllib3.connection.VerifiedHTTPSConnection object at 0x07E2EE30>: Failed to establish a new connection: [Errno 11001] getaddrinfo failed'))\n",
      "collecting... 879324929669443584\n",
      "Time out error caught. Failed to send request: HTTPSConnectionPool(host='api.twitter.com', port=443): Max retries exceeded with url: /1.1/followers/ids.json?cursor=-1&user_id=879324929669443584 (Caused by NewConnectionError('<urllib3.connection.VerifiedHTTPSConnection object at 0x056BBD70>: Failed to establish a new connection: [Errno 11001] getaddrinfo failed'))\n",
      "collecting... 18266825\n",
      "Time out error caught. Failed to send request: HTTPSConnectionPool(host='api.twitter.com', port=443): Max retries exceeded with url: /1.1/followers/ids.json?cursor=-1&user_id=18266825 (Caused by NewConnectionError('<urllib3.connection.VerifiedHTTPSConnection object at 0x056BBD70>: Failed to establish a new connection: [Errno 11001] getaddrinfo failed'))\n",
      "collecting... 927513257946083329\n",
      "Time out error caught. Failed to send request: HTTPSConnectionPool(host='api.twitter.com', port=443): Max retries exceeded with url: /1.1/followers/ids.json?cursor=-1&user_id=927513257946083329 (Caused by NewConnectionError('<urllib3.connection.VerifiedHTTPSConnection object at 0x0926DAB0>: Failed to establish a new connection: [Errno 11001] getaddrinfo failed'))\n",
      "collecting... 63668427\n",
      "Time out error caught. Failed to send request: HTTPSConnectionPool(host='api.twitter.com', port=443): Max retries exceeded with url: /1.1/followers/ids.json?cursor=-1&user_id=63668427 (Caused by NewConnectionError('<urllib3.connection.VerifiedHTTPSConnection object at 0x07C15850>: Failed to establish a new connection: [Errno 11001] getaddrinfo failed'))\n",
      "collecting... 65666255\n",
      "Time out error caught. Failed to send request: HTTPSConnectionPool(host='api.twitter.com', port=443): Max retries exceeded with url: /1.1/followers/ids.json?cursor=-1&user_id=65666255 (Caused by NewConnectionError('<urllib3.connection.VerifiedHTTPSConnection object at 0x05FF1170>: Failed to establish a new connection: [Errno 11001] getaddrinfo failed'))\n",
      "collecting... 2827042006\n",
      "Time out error caught. Failed to send request: HTTPSConnectionPool(host='api.twitter.com', port=443): Max retries exceeded with url: /1.1/followers/ids.json?cursor=-1&user_id=2827042006 (Caused by NewConnectionError('<urllib3.connection.VerifiedHTTPSConnection object at 0x0591C890>: Failed to establish a new connection: [Errno 11001] getaddrinfo failed'))\n",
      "collecting... 407754462\n",
      "Time out error caught. Failed to send request: HTTPSConnectionPool(host='api.twitter.com', port=443): Max retries exceeded with url: /1.1/followers/ids.json?cursor=-1&user_id=407754462 (Caused by NewConnectionError('<urllib3.connection.VerifiedHTTPSConnection object at 0x07149CB0>: Failed to establish a new connection: [Errno 11001] getaddrinfo failed'))\n",
      "collecting... 22274790\n"
     ]
    }
   ],
   "source": [
    "# populate existing user_ids\n",
    "records = db['followers']\n",
    "populated_documents = records.find()\n",
    "populated_user_ids = []\n",
    "for document in populated_documents:\n",
    "    populated_user_ids.append(document['user_id'])\n",
    "for user_id in ROOT_USERS:\n",
    "    if user_id not in populated_user_ids:\n",
    "        try:\n",
    "            records = db['followers']               \n",
    "            records.insert_one({'user_id' : user_id, 'followers' : []})\n",
    "            try:\n",
    "                print('collecting...', user_id)\n",
    "                for follower in tweepy.Cursor(api.followers_ids, user_id = user_id).items(10000000):\n",
    "                    records.update_one({'user_id' : user_id}, {'$push' : {'followers' : follower}})\n",
    "#                     print(follower)\n",
    "            except tweepy.TweepError as e:\n",
    "                if 'Failed to send request:' in e.reason:\n",
    "                    print('Time out error caught.', e)\n",
    "                    time.sleep(180)\n",
    "                    continue\n",
    "        except Exception as e:\n",
    "            print(e, ' OR Connection failed')\n",
    "            time.sleep(180)\n",
    "            continue"
   ]
  },
  {
   "cell_type": "markdown",
   "metadata": {},
   "source": [
    "### TODO\n",
    "follower array lengh and number of followrs of the user must be equal, if not fill missed user followers"
   ]
  }
 ],
 "metadata": {
  "kernelspec": {
   "display_name": "Python 3",
   "language": "python",
   "name": "python3"
  },
  "language_info": {
   "codemirror_mode": {
    "name": "ipython",
    "version": 3
   },
   "file_extension": ".py",
   "mimetype": "text/x-python",
   "name": "python",
   "nbconvert_exporter": "python",
   "pygments_lexer": "ipython3",
   "version": "3.7.6"
  }
 },
 "nbformat": 4,
 "nbformat_minor": 4
}
